Workbook
Name DESCRIPTORS: 'Helper (Do Not Delete)'!$T$3:$W$7
Name FemaleLearners: 'INPUT DATA'!$P$9:$P$58
Name MaleLearners: 'INPUT DATA'!$J$9:$J$58
Name NewTransmu: 'Helper (Do Not Delete)'!$H$3:$K$43

Sheet INPUT DATA
B2: INPUT DATA SHEET
B5: INFORMATION | H5: LEARNERS' NAMES
D8: REGION: | E8: X | I8: MALE | O8: FEMALE
D9: DIVISION: | E9: EDUCATORS FILES | I9: 1 | O9: 1
D10: SCHOOL NAME: | E10: EFILES NATIONAL HIGH SCHOOL | I10: 2 | O10: 2
D11: SCHOOL ID: | E11: 123456 | I11: 3 | O11: 3
D12: SCHOOL YEAR: | E12: 2026-2027 | I12: 4 | O12: 4
I13: 5 | O13: 5
D14: GRADE & SECTION: | E14: VI - MASIPAG | I14: 6 | O14: 6
D15: SUBJECT: | E15: MAPEH | I15: 7 | O15: 7
I16: 8 | O16: 8
D17: TEACHER: | E17: SAMUEL A. SILVERIO | I17: 9 | O17: 9
D18: POSITION: | E18: TEACHER VI | I18: 10 | O18: 10
I19: 11 | O19: 11
D20: SCHOOL HEAD: | E20: PEDRO MAPAGBIGAY | I20: 12 | O20: 12
D21: POSITION: | E21: PRINCIPAL III | I21: 13 | O21: 13
I22: 14 | O22: 14
I23: 15 | O23: 15
I24: 16 | O24: 16
E25: This Excel-based tool is not the official E-Class Record issued by the Department of Education (DepEd). It is an independently developed EduFilesPH resource designed to assist teachers in recording, computing, organizing, and monitoring learners’ grades more efficiently. The assessment components, grading weights, grade computation, transmutation, descriptors, and reporting features implemented in this tool are based on and aligned with DepEd Order No. 015, s. 2026, titled “Revised Guidelines on Classroom Assessment, Grading System, and Awards and Recognition for the K to 12 Basic Education Program.” Should DepEd release future orders, memoranda, official templates, or revised guidelines that introduce changes affecting classroom assessment, grading, or learner reporting, EduFilesPH may review and update this tool to maintain alignment with the latest applicable policies. | I25: 17 | O25: 17
I26: 18 | O26: 18
I27: 19 | O27: 19
I28: 20 | O28: 20
I29: 21 | O29: 21
I30: 22 | O30: 22
I31: 23 | O31: 23
I32: 24 | O32: 24
I33: 25 | O33: 25
I34: 26 | O34: 26
I35: 27 | O35: 27
I36: 28 | O36: 28
I37: 29 | O37: 29
... I58: 50 | O58: 50

Sheet MA_T1
A1: Class Record
B4: REGION | G4: ='INPUT DATA'!E8 -> X | I4: DIVISION | L4: ='INPUT DATA'!E9 -> EDUCATORS FILES
B5: SCHOOL NAME | G5: ='INPUT DATA'!E10 -> EFILES NATIONAL HIGH SCHOOL | Q5: SCHOOL ID | S5: ='INPUT DATA'!E11 -> 123456 | V5: SCHOOL YEAR | AB5: ='INPUT DATA'!E12 -> 2026-2027
A7: TERM 1 | F7: GRADE & SECTION: | J7: ='INPUT DATA'!E14 -> VI - MASIPAG | N7: TEACHER: | Q7: ='INPUT DATA'!E17 -> SAMUEL A. SILVERIO | Z7: SUBJECT: | AB7: MUSIC AND ARTS
B8: LEARNERS' NAMES | F8: WRITTEN / ORAL WORKS (20%) | N8: PRODUCT / PERFORMANCE TASKS (60%) | T8: SUMMATIVE TESTS AND TERM EXAMINATIONS (20%) | AB8: Initial Grade | AC8: TERM GRADE | AD8: DESCRIPTOR
F9: 1 | G9: 2 | H9: 3 | I9: 4 | J9: 5 | K9: Total | L9: PS | M9: WS | N9: 1 | O9: 2 | P9: 3 | Q9: Total | R9: PS | S9: WS | T9: ST1 | U9: ST2 | V9: TE | W9: WS ST1 (30%) | X9: WS ST2 (30%) | Y9: WS TE (40%) | Z9: PS ST&TE | AA9: WS ST&TE
B10: HIGHEST POSSIBLE SCORE | K10: =IF(COUNT($F10:$J10)=0,"",SUM($F10:$J10)) | L10: 100 | M10: 0.2 | Q10: =IF(COUNT($N10:$P10)=0,"",SUM($N10:$P10)) | R10: 100 | S10: 0.6 | W10: 30 | X10: 30 | Y10: 40 | Z10: 100 | AA10: 0.2
B11: MALE | AQ11: ST1 | AR11: ST2 | AS11: TE
A12: 1 | B12: ='INPUT DATA'!J9 -> 0 | K12: =IF(COUNT($F12:$J12)=0,"",SUM($F12:$J12)) | L12: =IF(ISERROR(IF($K12="","",ROUND(($K12/$K$10)*$L$10,2))),"",IF($K12="","",ROUND(($K12/$K$10)*$L$10,2))) | M12: =IF($L12="","",ROUND($L12*$M$10,2)) | Q12: =IF(COUNT($N12:$P12)=0,"",SUM($N12:$P12)) | R12: =IF(ISERROR(IF($Q12="","",ROUND(($Q12/$Q$10)*$R$10,2))),"",IF($Q12="","",ROUND(($Q12/$Q$10)*$R$10,2))) | S12: =IF($R12="","",ROUND($R12*$S$10,2)) | W12: =IF(OR(T12="",$T$10=""),"",(T12/$T$10)*$W$10) | X12: =IF(OR(U12="",$U$10=""),"",(U12/$U$10)*$X$10) | Y12: =IF(OR(V12="",$V$10=""),"",(V12/$V$10)*$Y$10) | Z12: =IF(COUNT($W12:$Y12)=0,"",IFERROR(ROUND((SUM($W12:$Y12)/SUM($W$10:$Y$10))*$Z$10,2),"")) | AA12: =IF($Z12="","",ROUND($Z12*$AA$10,2)) | AB12: =IF(ISERROR(IF($Z12="","",ROUND(SUM($M12,$S12,$AA12),2))),"",IF($Z12="","",ROUND(SUM($M12,$S12,$AA12),2))) | AC12: =IF(ISERROR(IF($Z12="","",VLOOKUP(AB12,NewTransmu,4,TRUE))),"",IF($Z12="","",VLOOKUP(AB12,NewTransmu,4,TRUE))) | AD12: =IF(ISERROR(IF(AC12="","",VLOOKUP(AC12,DESCRIPTORS,4,TRUE))),"",IF(AC12="","",VLOOKUP(AC12,DESCRIPTORS,4,TRUE))) | AQ12: =(T12/$T$10)*100 -> #DIV/0! | AR12: =(U12/$U$10)*100 -> #DIV/0! | AS12: =(V12/$V$10)*100 -> #DIV/0!
A13: 2 | B13: ='INPUT DATA'!J10 -> 0 | K13: =IF(COUNT($F13:$J13)=0,"",SUM($F13:$J13)) | L13: =IF(ISERROR(IF($K13="","",ROUND(($K13/$K$10)*$L$10,2))),"",IF($K13="","",ROUND(($K13/$K$10)*$L$10,2))) | M13: =IF($L13="","",ROUND($L13*$M$10,2)) | Q13: =IF(COUNT($N13:$P13)=0,"",SUM($N13:$P13)) | R13: =IF(ISERROR(IF($Q13="","",ROUND(($Q13/$Q$10)*$R$10,2))),"",IF($Q13="","",ROUND(($Q13/$Q$10)*$R$10,2))) | S13: =IF($R13="","",ROUND($R13*$S$10,2)) | W13: =IF(OR(T13="",$T$10=""),"",(T13/$T$10)*$W$10) | X13: =IF(OR(U13="",$U$10=""),"",(U13/$U$10)*$X$10) | Y13: =IF(OR(V13="",$V$10=""),"",(V13/$V$10)*$Y$10) | Z13: =IF(COUNT($W13:$Y13)=0,"",IFERROR(ROUND((SUM($W13:$Y13)/SUM($W$10:$Y$10))*$Z$10,2),"")) | AA13: =IF($Z13="","",ROUND($Z13*$AA$10,2)) | AB13: =IF(ISERROR(IF($Z13="","",ROUND(SUM($M13,$S13,$AA13),2))),"",IF($Z13="","",ROUND(SUM($M13,$S13,$AA13),2))) | AC13: =IF(ISERROR(IF($Z13="","",VLOOKUP(AB13,NewTransmu,4,TRUE))),"",IF($Z13="","",VLOOKUP(AB13,NewTransmu,4,TRUE))) | AD13: =IF(ISERROR(IF(AC13="","",VLOOKUP(AC13,DESCRIPTORS,4,TRUE))),"",IF(AC13="","",VLOOKUP(AC13,DESCRIPTORS,4,TRUE))) | AQ13: =(T13/$T$10)*100 -> #DIV/0! | AR13: =(U13/$U$10)*100 -> #DIV/0! | AS13: =(V13/$V$10)*100 -> #DIV/0!
A14: 3 | B14: ='INPUT DATA'!J11 -> 0 | K14: =IF(COUNT($F14:$J14)=0,"",SUM($F14:$J14)) | L14: =IF(ISERROR(IF($K14="","",ROUND(($K14/$K$10)*$L$10,2))),"",IF($K14="","",ROUND(($K14/$K$10)*$L$10,2))) | M14: =IF($L14="","",ROUND($L14*$M$10,2)) | Q14: =IF(COUNT($N14:$P14)=0,"",SUM($N14:$P14)) | R14: =IF(ISERROR(IF($Q14="","",ROUND(($Q14/$Q$10)*$R$10,2))),"",IF($Q14="","",ROUND(($Q14/$Q$10)*$R$10,2))) | S14: =IF($R14="","",ROUND($R14*$S$10,2)) | W14: =IF(OR(T14="",$T$10=""),"",(T14/$T$10)*$W$10) | X14: =IF(OR(U14="",$U$10=""),"",(U14/$U$10)*$X$10) | Y14: =IF(OR(V14="",$V$10=""),"",(V14/$V$10)*$Y$10) | Z14: =IF(COUNT($W14:$Y14)=0,"",IFERROR(ROUND((SUM($W14:$Y14)/SUM($W$10:$Y$10))*$Z$10,2),"")) | AA14: =IF($Z14="","",ROUND($Z14*$AA$10,2)) | AB14: =IF(ISERROR(IF($Z14="","",ROUND(SUM($M14,$S14,$AA14),2))),"",IF($Z14="","",ROUND(SUM($M14,$S14,$AA14),2))) | AC14: =IF(ISERROR(IF($Z14="","",VLOOKUP(AB14,NewTransmu,4,TRUE))),"",IF($Z14="","",VLOOKUP(AB14,NewTransmu,4,TRUE))) | AD14: =IF(ISERROR(IF(AC14="","",VLOOKUP(AC14,DESCRIPTORS,4,TRUE))),"",IF(AC14="","",VLOOKUP(AC14,DESCRIPTORS,4,TRUE))) | AQ14: =(T14/$T$10)*100 -> #DIV/0! | AR14: =(U14/$U$10)*100 -> #DIV/0! | AS14: =(V14/$V$10)*100 -> #DIV/0!
A15: 4 | B15: ='INPUT DATA'!J12 -> 0 | K15: =IF(COUNT($F15:$J15)=0,"",SUM($F15:$J15)) | L15: =IF(ISERROR(IF($K15="","",ROUND(($K15/$K$10)*$L$10,2))),"",IF($K15="","",ROUND(($K15/$K$10)*$L$10,2))) | M15: =IF($L15="","",ROUND($L15*$M$10,2)) | Q15: =IF(COUNT($N15:$P15)=0,"",SUM($N15:$P15)) | R15: =IF(ISERROR(IF($Q15="","",ROUND(($Q15/$Q$10)*$R$10,2))),"",IF($Q15="","",ROUND(($Q15/$Q$10)*$R$10,2))) | S15: =IF($R15="","",ROUND($R15*$S$10,2)) | W15: =IF(OR(T15="",$T$10=""),"",(T15/$T$10)*$W$10) | X15: =IF(OR(U15="",$U$10=""),"",(U15/$U$10)*$X$10) | Y15: =IF(OR(V15="",$V$10=""),"",(V15/$V$10)*$Y$10) | Z15: =IF(COUNT($W15:$Y15)=0,"",IFERROR(ROUND((SUM($W15:$Y15)/SUM($W$10:$Y$10))*$Z$10,2),"")) | AA15: =IF($Z15="","",ROUND($Z15*$AA$10,2)) | AB15: =IF(ISERROR(IF($Z15="","",ROUND(SUM($M15,$S15,$AA15),2))),"",IF($Z15="","",ROUND(SUM($M15,$S15,$AA15),2))) | AC15: =IF(ISERROR(IF($Z15="","",VLOOKUP(AB15,NewTransmu,4,TRUE))),"",IF($Z15="","",VLOOKUP(AB15,NewTransmu,4,TRUE))) | AD15: =IF(ISERROR(IF(AC15="","",VLOOKUP(AC15,DESCRIPTORS,4,TRUE))),"",IF(AC15="","",VLOOKUP(AC15,DESCRIPTORS,4,TRUE))) | AQ15: =(T15/$T$10)*100 -> #DIV/0! | AR15: =(U15/$U$10)*100 -> #DIV/0! | AS15: =(V15/$V$10)*100 -> #DIV/0!
A16: 5 | B16: ='INPUT DATA'!J13 -> 0 | K16: =IF(COUNT($F16:$J16)=0,"",SUM($F16:$J16)) | L16: =IF(ISERROR(IF($K16="","",ROUND(($K16/$K$10)*$L$10,2))),"",IF($K16="","",ROUND(($K16/$K$10)*$L$10,2))) | M16: =IF($L16="","",ROUND($L16*$M$10,2)) | Q16: =IF(COUNT($N16:$P16)=0,"",SUM($N16:$P16)) | R16: =IF(ISERROR(IF($Q16="","",ROUND(($Q16/$Q$10)*$R$10,2))),"",IF($Q16="","",ROUND(($Q16/$Q$10)*$R$10,2))) | S16: =IF($R16="","",ROUND($R16*$S$10,2)) | W16: =IF(OR(T16="",$T$10=""),"",(T16/$T$10)*$W$10) | X16: =IF(OR(U16="",$U$10=""),"",(U16/$U$10)*$X$10) | Y16: =IF(OR(V16="",$V$10=""),"",(V16/$V$10)*$Y$10) | Z16: =IF(COUNT($W16:$Y16)=0,"",IFERROR(ROUND((SUM($W16:$Y16)/SUM($W$10:$Y$10))*$Z$10,2),"")) | AA16: =IF($Z16="","",ROUND($Z16*$AA$10,2)) | AB16: =IF(ISERROR(IF($Z16="","",ROUND(SUM($M16,$S16,$AA16),2))),"",IF($Z16="","",ROUND(SUM($M16,$S16,$AA16),2))) | AC16: =IF(ISERROR(IF($Z16="","",VLOOKUP(AB16,NewTransmu,4,TRUE))),"",IF($Z16="","",VLOOKUP(AB16,NewTransmu,4,TRUE))) | AD16: =IF(ISERROR(IF(AC16="","",VLOOKUP(AC16,DESCRIPTORS,4,TRUE))),"",IF(AC16="","",VLOOKUP(AC16,DESCRIPTORS,4,TRUE))) | AQ16: =(T16/$T$10)*100 -> #DIV/0! | AR16: =(U16/$U$10)*100 -> #DIV/0! | AS16: =(V16/$V$10)*100 -> #DIV/0!
A17: 6 | B17: ='INPUT DATA'!J14 -> 0 | K17: =IF(COUNT($F17:$J17)=0,"",SUM($F17:$J17)) | L17: =IF(ISERROR(IF($K17="","",ROUND(($K17/$K$10)*$L$10,2))),"",IF($K17="","",ROUND(($K17/$K$10)*$L$10,2))) | M17: =IF($L17="","",ROUND($L17*$M$10,2)) | Q17: =IF(COUNT($N17:$P17)=0,"",SUM($N17:$P17)) | R17: =IF(ISERROR(IF($Q17="","",ROUND(($Q17/$Q$10)*$R$10,2))),"",IF($Q17="","",ROUND(($Q17/$Q$10)*$R$10,2))) | S17: =IF($R17="","",ROUND($R17*$S$10,2)) | W17: =IF(OR(T17="",$T$10=""),"",(T17/$T$10)*$W$10) | X17: =IF(OR(U17="",$U$10=""),"",(U17/$U$10)*$X$10) | Y17: =IF(OR(V17="",$V$10=""),"",(V17/$V$10)*$Y$10) | Z17: =IF(COUNT($W17:$Y17)=0,"",IFERROR(ROUND((SUM($W17:$Y17)/SUM($W$10:$Y$10))*$Z$10,2),"")) | AA17: =IF($Z17="","",ROUND($Z17*$AA$10,2)) | AB17: =IF(ISERROR(IF($Z17="","",ROUND(SUM($M17,$S17,$AA17),2))),"",IF($Z17="","",ROUND(SUM($M17,$S17,$AA17),2))) | AC17: =IF(ISERROR(IF($Z17="","",VLOOKUP(AB17,NewTransmu,4,TRUE))),"",IF($Z17="","",VLOOKUP(AB17,NewTransmu,4,TRUE))) | AD17: =IF(ISERROR(IF(AC17="","",VLOOKUP(AC17,DESCRIPTORS,4,TRUE))),"",IF(AC17="","",VLOOKUP(AC17,DESCRIPTORS,4,TRUE))) | AQ17: =(T17/$T$10)*100 -> #DIV/0! | AR17: =(U17/$U$10)*100 -> #DIV/0! | AS17: =(V17/$V$10)*100 -> #DIV/0!
A18: 7 | B18: ='INPUT DATA'!J15 -> 0 | K18: =IF(COUNT($F18:$J18)=0,"",SUM($F18:$J18)) | L18: =IF(ISERROR(IF($K18="","",ROUND(($K18/$K$10)*$L$10,2))),"",IF($K18="","",ROUND(($K18/$K$10)*$L$10,2))) | M18: =IF($L18="","",ROUND($L18*$M$10,2)) | Q18: =IF(COUNT($N18:$P18)=0,"",SUM($N18:$P18)) | R18: =IF(ISERROR(IF($Q18="","",ROUND(($Q18/$Q$10)*$R$10,2))),"",IF($Q18="","",ROUND(($Q18/$Q$10)*$R$10,2))) | S18: =IF($R18="","",ROUND($R18*$S$10,2)) | W18: =IF(OR(T18="",$T$10=""),"",(T18/$T$10)*$W$10) | X18: =IF(OR(U18="",$U$10=""),"",(U18/$U$10)*$X$10) | Y18: =IF(OR(V18="",$V$10=""),"",(V18/$V$10)*$Y$10) | Z18: =IF(COUNT($W18:$Y18)=0,"",IFERROR(ROUND((SUM($W18:$Y18)/SUM($W$10:$Y$10))*$Z$10,2),"")) | AA18: =IF($Z18="","",ROUND($Z18*$AA$10,2)) | AB18: =IF(ISERROR(IF($Z18="","",ROUND(SUM($M18,$S18,$AA18),2))),"",IF($Z18="","",ROUND(SUM($M18,$S18,$AA18),2))) | AC18: =IF(ISERROR(IF($Z18="","",VLOOKUP(AB18,NewTransmu,4,TRUE))),"",IF($Z18="","",VLOOKUP(AB18,NewTransmu,4,TRUE))) | AD18: =IF(ISERROR(IF(AC18="","",VLOOKUP(AC18,DESCRIPTORS,4,TRUE))),"",IF(AC18="","",VLOOKUP(AC18,DESCRIPTORS,4,TRUE))) | AQ18: =(T18/$T$10)*100 -> #DIV/0! | AR18: =(U18/$U$10)*100 -> #DIV/0! | AS18: =(V18/$V$10)*100 -> #DIV/0!
A19: 8 | B19: ='INPUT DATA'!J16 -> 0 | K19: =IF(COUNT($F19:$J19)=0,"",SUM($F19:$J19)) | L19: =IF(ISERROR(IF($K19="","",ROUND(($K19/$K$10)*$L$10,2))),"",IF($K19="","",ROUND(($K19/$K$10)*$L$10,2))) | M19: =IF($L19="","",ROUND($L19*$M$10,2)) | Q19: =IF(COUNT($N19:$P19)=0,"",SUM($N19:$P19)) | R19: =IF(ISERROR(IF($Q19="","",ROUND(($Q19/$Q$10)*$R$10,2))),"",IF($Q19="","",ROUND(($Q19/$Q$10)*$R$10,2))) | S19: =IF($R19="","",ROUND($R19*$S$10,2)) | W19: =IF(OR(T19="",$T$10=""),"",(T19/$T$10)*$W$10) | X19: =IF(OR(U19="",$U$10=""),"",(U19/$U$10)*$X$10) | Y19: =IF(OR(V19="",$V$10=""),"",(V19/$V$10)*$Y$10) | Z19: =IF(COUNT($W19:$Y19)=0,"",IFERROR(ROUND((SUM($W19:$Y19)/SUM($W$10:$Y$10))*$Z$10,2),"")) | AA19: =IF($Z19="","",ROUND($Z19*$AA$10,2)) | AB19: =IF(ISERROR(IF($Z19="","",ROUND(SUM($M19,$S19,$AA19),2))),"",IF($Z19="","",ROUND(SUM($M19,$S19,$AA19),2))) | AC19: =IF(ISERROR(IF($Z19="","",VLOOKUP(AB19,NewTransmu,4,TRUE))),"",IF($Z19="","",VLOOKUP(AB19,NewTransmu,4,TRUE))) | AD19: =IF(ISERROR(IF(AC19="","",VLOOKUP(AC19,DESCRIPTORS,4,TRUE))),"",IF(AC19="","",VLOOKUP(AC19,DESCRIPTORS,4,TRUE))) | AQ19: =(T19/$T$10)*100 -> #DIV/0! | AR19: =(U19/$U$10)*100 -> #DIV/0! | AS19: =(V19/$V$10)*100 -> #DIV/0!
A20: 9 | B20: ='INPUT DATA'!J17 -> 0 | K20: =IF(COUNT($F20:$J20)=0,"",SUM($F20:$J20)) | L20: =IF(ISERROR(IF($K20="","",ROUND(($K20/$K$10)*$L$10,2))),"",IF($K20="","",ROUND(($K20/$K$10)*$L$10,2))) | M20: =IF($L20="","",ROUND($L20*$M$10,2)) | Q20: =IF(COUNT($N20:$P20)=0,"",SUM($N20:$P20)) | R20: =IF(ISERROR(IF($Q20="","",ROUND(($Q20/$Q$10)*$R$10,2))),"",IF($Q20="","",ROUND(($Q20/$Q$10)*$R$10,2))) | S20: =IF($R20="","",ROUND($R20*$S$10,2)) | W20: =IF(OR(T20="",$T$10=""),"",(T20/$T$10)*$W$10) | X20: =IF(OR(U20="",$U$10=""),"",(U20/$U$10)*$X$10) | Y20: =IF(OR(V20="",$V$10=""),"",(V20/$V$10)*$Y$10) | Z20: =IF(COUNT($W20:$Y20)=0,"",IFERROR(ROUND((SUM($W20:$Y20)/SUM($W$10:$Y$10))*$Z$10,2),"")) | AA20: =IF($Z20="","",ROUND($Z20*$AA$10,2)) | AB20: =IF(ISERROR(IF($Z20="","",ROUND(SUM($M20,$S20,$AA20),2))),"",IF($Z20="","",ROUND(SUM($M20,$S20,$AA20),2))) | AC20: =IF(ISERROR(IF($Z20="","",VLOOKUP(AB20,NewTransmu,4,TRUE))),"",IF($Z20="","",VLOOKUP(AB20,NewTransmu,4,TRUE))) | AD20: =IF(ISERROR(IF(AC20="","",VLOOKUP(AC20,DESCRIPTORS,4,TRUE))),"",IF(AC20="","",VLOOKUP(AC20,DESCRIPTORS,4,TRUE))) | AQ20: =(T20/$T$10)*100 -> #DIV/0! | AR20: =(U20/$U$10)*100 -> #DIV/0! | AS20: =(V20/$V$10)*100 -> #DIV/0!
A21: 10 | B21: ='INPUT DATA'!J18 -> 0 | K21: =IF(COUNT($F21:$J21)=0,"",SUM($F21:$J21)) | L21: =IF(ISERROR(IF($K21="","",ROUND(($K21/$K$10)*$L$10,2))),"",IF($K21="","",ROUND(($K21/$K$10)*$L$10,2))) | M21: =IF($L21="","",ROUND($L21*$M$10,2)) | Q21: =IF(COUNT($N21:$P21)=0,"",SUM($N21:$P21)) | R21: =IF(ISERROR(IF($Q21="","",ROUND(($Q21/$Q$10)*$R$10,2))),"",IF($Q21="","",ROUND(($Q21/$Q$10)*$R$10,2))) | S21: =IF($R21="","",ROUND($R21*$S$10,2)) | W21: =IF(OR(T21="",$T$10=""),"",(T21/$T$10)*$W$10) | X21: =IF(OR(U21="",$U$10=""),"",(U21/$U$10)*$X$10) | Y21: =IF(OR(V21="",$V$10=""),"",(V21/$V$10)*$Y$10) | Z21: =IF(COUNT($W21:$Y21)=0,"",IFERROR(ROUND((SUM($W21:$Y21)/SUM($W$10:$Y$10))*$Z$10,2),"")) | AA21: =IF($Z21="","",ROUND($Z21*$AA$10,2)) | AB21: =IF(ISERROR(IF($Z21="","",ROUND(SUM($M21,$S21,$AA21),2))),"",IF($Z21="","",ROUND(SUM($M21,$S21,$AA21),2))) | AC21: =IF(ISERROR(IF($Z21="","",VLOOKUP(AB21,NewTransmu,4,TRUE))),"",IF($Z21="","",VLOOKUP(AB21,NewTransmu,4,TRUE))) | AD21: =IF(ISERROR(IF(AC21="","",VLOOKUP(AC21,DESCRIPTORS,4,TRUE))),"",IF(AC21="","",VLOOKUP(AC21,DESCRIPTORS,4,TRUE))) | AQ21: =(T21/$T$10)*100 -> #DIV/0! | AR21: =(U21/$U$10)*100 -> #DIV/0! | AS21: =(V21/$V$10)*100 -> #DIV/0!
A22: 11 | B22: ='INPUT DATA'!J19 -> 0 | K22: =IF(COUNT($F22:$J22)=0,"",SUM($F22:$J22)) | L22: =IF(ISERROR(IF($K22="","",ROUND(($K22/$K$10)*$L$10,2))),"",IF($K22="","",ROUND(($K22/$K$10)*$L$10,2))) | M22: =IF($L22="","",ROUND($L22*$M$10,2)) | Q22: =IF(COUNT($N22:$P22)=0,"",SUM($N22:$P22)) | R22: =IF(ISERROR(IF($Q22="","",ROUND(($Q22/$Q$10)*$R$10,2))),"",IF($Q22="","",ROUND(($Q22/$Q$10)*$R$10,2))) | S22: =IF($R22="","",ROUND($R22*$S$10,2)) | W22: =IF(OR(T22="",$T$10=""),"",(T22/$T$10)*$W$10) | X22: =IF(OR(U22="",$U$10=""),"",(U22/$U$10)*$X$10) | Y22: =IF(OR(V22="",$V$10=""),"",(V22/$V$10)*$Y$10) | Z22: =IF(COUNT($W22:$Y22)=0,"",IFERROR(ROUND((SUM($W22:$Y22)/SUM($W$10:$Y$10))*$Z$10,2),"")) | AA22: =IF($Z22="","",ROUND($Z22*$AA$10,2)) | AB22: =IF(ISERROR(IF($Z22="","",ROUND(SUM($M22,$S22,$AA22),2))),"",IF($Z22="","",ROUND(SUM($M22,$S22,$AA22),2))) | AC22: =IF(ISERROR(IF($Z22="","",VLOOKUP(AB22,NewTransmu,4,TRUE))),"",IF($Z22="","",VLOOKUP(AB22,NewTransmu,4,TRUE))) | AD22: =IF(ISERROR(IF(AC22="","",VLOOKUP(AC22,DESCRIPTORS,4,TRUE))),"",IF(AC22="","",VLOOKUP(AC22,DESCRIPTORS,4,TRUE))) | AQ22: =(T22/$T$10)*100 -> #DIV/0! | AR22: =(U22/$U$10)*100 -> #DIV/0! | AS22: =(V22/$V$10)*100 -> #DIV/0!
A23: 12 | B23: ='INPUT DATA'!J20 -> 0 | K23: =IF(COUNT($F23:$J23)=0,"",SUM($F23:$J23)) | L23: =IF(ISERROR(IF($K23="","",ROUND(($K23/$K$10)*$L$10,2))),"",IF($K23="","",ROUND(($K23/$K$10)*$L$10,2))) | M23: =IF($L23="","",ROUND($L23*$M$10,2)) | Q23: =IF(COUNT($N23:$P23)=0,"",SUM($N23:$P23)) | R23: =IF(ISERROR(IF($Q23="","",ROUND(($Q23/$Q$10)*$R$10,2))),"",IF($Q23="","",ROUND(($Q23/$Q$10)*$R$10,2))) | S23: =IF($R23="","",ROUND($R23*$S$10,2)) | W23: =IF(OR(T23="",$T$10=""),"",(T23/$T$10)*$W$10) | X23: =IF(OR(U23="",$U$10=""),"",(U23/$U$10)*$X$10) | Y23: =IF(OR(V23="",$V$10=""),"",(V23/$V$10)*$Y$10) | Z23: =IF(COUNT($W23:$Y23)=0,"",IFERROR(ROUND((SUM($W23:$Y23)/SUM($W$10:$Y$10))*$Z$10,2),"")) | AA23: =IF($Z23="","",ROUND($Z23*$AA$10,2)) | AB23: =IF(ISERROR(IF($Z23="","",ROUND(SUM($M23,$S23,$AA23),2))),"",IF($Z23="","",ROUND(SUM($M23,$S23,$AA23),2))) | AC23: =IF(ISERROR(IF($Z23="","",VLOOKUP(AB23,NewTransmu,4,TRUE))),"",IF($Z23="","",VLOOKUP(AB23,NewTransmu,4,TRUE))) | AD23: =IF(ISERROR(IF(AC23="","",VLOOKUP(AC23,DESCRIPTORS,4,TRUE))),"",IF(AC23="","",VLOOKUP(AC23,DESCRIPTORS,4,TRUE))) | AQ23: =(T23/$T$10)*100 -> #DIV/0! | AR23: =(U23/$U$10)*100 -> #DIV/0! | AS23: =(V23/$V$10)*100 -> #DIV/0!
... A61: 50 | B61: ='INPUT DATA'!J58 -> 0 | K61: =IF(COUNT($F61:$J61)=0,"",SUM($F61:$J61)) | L61: =IF(ISERROR(IF($K61="","",ROUND(($K61/$K$10)*$L$10,2))),"",IF($K61="","",ROUND(($K61/$K$10)*$L$10,2))) | M61: =IF($L61="","",ROUND($L61*$M$10,2)) | Q61: =IF(COUNT($N61:$P61)=0,"",SUM($N61:$P61)) | R61: =IF(ISERROR(IF($Q61="","",ROUND(($Q61/$Q$10)*$R$10,2))),"",IF($Q61="","",ROUND(($Q61/$Q$10)*$R$10,2))) | S61: =IF($R61="","",ROUND($R61*$S$10,2)) | W61: =IF(OR(T61="",$T$10=""),"",(T61/$T$10)*$W$10) | X61: =IF(OR(U61="",$U$10=""),"",(U61/$U$10)*$X$10) | Y61: =IF(OR(V61="",$V$10=""),"",(V61/$V$10)*$Y$10) | Z61: =IF(COUNT($W61:$Y61)=0,"",IFERROR(ROUND((SUM($W61:$Y61)/SUM($W$10:$Y$10))*$Z$10,2),"")) | AA61: =IF($Z61="","",ROUND($Z61*$AA$10,2)) | AB61: =IF(ISERROR(IF($Z61="","",ROUND(SUM($M61,$S61,$AA61),2))),"",IF($Z61="","",ROUND(SUM($M61,$S61,$AA61),2))) | AC61: =IF(ISERROR(IF($Z61="","",VLOOKUP(AB61,NewTransmu,4,TRUE))),"",IF($Z61="","",VLOOKUP(AB61,NewTransmu,4,TRUE))) | AD61: =IF(ISERROR(IF(AC61="","",VLOOKUP(AC61,DESCRIPTORS,4,TRUE))),"",IF(AC61="","",VLOOKUP(AC61,DESCRIPTORS,4,TRUE))) | AQ61: =(T61/$T$10)*100 -> #DIV/0! | AR61: =(U61/$U$10)*100 -> #DIV/0! | AS61: =(V61/$V$10)*100 -> #DIV/0!
B62: FEMALE | AQ62: =(T62/$T$10)*100 -> #DIV/0! | AR62: =(U62/$U$10)*100 -> #DIV/0! | AS62: =(V62/$V$10)*100 -> #DIV/0!
A63: 1 | B63: ='INPUT DATA'!P9 -> 0 | K63: =IF(COUNT($F63:$J63)=0,"",SUM($F63:$J63)) | L63: =IF(ISERROR(IF($K63="","",ROUND(($K63/$K$10)*$L$10,2))),"",IF($K63="","",ROUND(($K63/$K$10)*$L$10,2))) | M63: =IF($L63="","",ROUND($L63*$M$10,2)) | Q63: =IF(COUNT($N63:$P63)=0,"",SUM($N63:$P63)) | R63: =IF(ISERROR(IF($Q63="","",ROUND(($Q63/$Q$10)*$R$10,2))),"",IF($Q63="","",ROUND(($Q63/$Q$10)*$R$10,2))) | S63: =IF($R63="","",ROUND($R63*$S$10,2)) | W63: =IF(OR(T63="",$T$10=""),"",(T63/$T$10)*$W$10) | X63: =IF(OR(U63="",$U$10=""),"",(U63/$U$10)*$X$10) | Y63: =IF(OR(V63="",$V$10=""),"",(V63/$V$10)*$Y$10) | Z63: =IF(COUNT($W63:$Y63)=0,"",IFERROR(ROUND((SUM($W63:$Y63)/SUM($W$10:$Y$10))*$Z$10,2),"")) | AA63: =IF($Z63="","",ROUND($Z63*$AA$10,2)) | AB63: =IF(ISERROR(IF($Z63="","",ROUND(SUM($M63,$S63,$AA63),2))),"",IF($Z63="","",ROUND(SUM($M63,$S63,$AA63),2))) | AC63: =IF(ISERROR(IF($Z63="","",VLOOKUP(AB63,NewTransmu,4,TRUE))),"",IF($Z63="","",VLOOKUP(AB63,NewTransmu,4,TRUE))) | AD63: =IF(ISERROR(IF(AC63="","",VLOOKUP(AC63,DESCRIPTORS,4,TRUE))),"",IF(AC63="","",VLOOKUP(AC63,DESCRIPTORS,4,TRUE))) | AQ63: =(T63/$T$10)*100 -> #DIV/0! | AR63: =(U63/$U$10)*100 -> #DIV/0! | AS63: =(V63/$V$10)*100 -> #DIV/0!
A64: 2 | B64: ='INPUT DATA'!P10 -> 0 | K64: =IF(COUNT($F64:$J64)=0,"",SUM($F64:$J64)) | L64: =IF(ISERROR(IF($K64="","",ROUND(($K64/$K$10)*$L$10,2))),"",IF($K64="","",ROUND(($K64/$K$10)*$L$10,2))) | M64: =IF($L64="","",ROUND($L64*$M$10,2)) | Q64: =IF(COUNT($N64:$P64)=0,"",SUM($N64:$P64)) | R64: =IF(ISERROR(IF($Q64="","",ROUND(($Q64/$Q$10)*$R$10,2))),"",IF($Q64="","",ROUND(($Q64/$Q$10)*$R$10,2))) | S64: =IF($R64="","",ROUND($R64*$S$10,2)) | W64: =IF(OR(T64="",$T$10=""),"",(T64/$T$10)*$W$10) | X64: =IF(OR(U64="",$U$10=""),"",(U64/$U$10)*$X$10) | Y64: =IF(OR(V64="",$V$10=""),"",(V64/$V$10)*$Y$10) | Z64: =IF(COUNT($W64:$Y64)=0,"",IFERROR(ROUND((SUM($W64:$Y64)/SUM($W$10:$Y$10))*$Z$10,2),"")) | AA64: =IF($Z64="","",ROUND($Z64*$AA$10,2)) | AB64: =IF(ISERROR(IF($Z64="","",ROUND(SUM($M64,$S64,$AA64),2))),"",IF($Z64="","",ROUND(SUM($M64,$S64,$AA64),2))) | AC64: =IF(ISERROR(IF($Z64="","",VLOOKUP(AB64,NewTransmu,4,TRUE))),"",IF($Z64="","",VLOOKUP(AB64,NewTransmu,4,TRUE))) | AD64: =IF(ISERROR(IF(AC64="","",VLOOKUP(AC64,DESCRIPTORS,4,TRUE))),"",IF(AC64="","",VLOOKUP(AC64,DESCRIPTORS,4,TRUE))) | AQ64: =(T64/$T$10)*100 -> #DIV/0! | AR64: =(U64/$U$10)*100 -> #DIV/0! | AS64: =(V64/$V$10)*100 -> #DIV/0!
A65: 3 | B65: ='INPUT DATA'!P11 -> 0 | K65: =IF(COUNT($F65:$J65)=0,"",SUM($F65:$J65)) | L65: =IF(ISERROR(IF($K65="","",ROUND(($K65/$K$10)*$L$10,2))),"",IF($K65="","",ROUND(($K65/$K$10)*$L$10,2))) | M65: =IF($L65="","",ROUND($L65*$M$10,2)) | Q65: =IF(COUNT($N65:$P65)=0,"",SUM($N65:$P65)) | R65: =IF(ISERROR(IF($Q65="","",ROUND(($Q65/$Q$10)*$R$10,2))),"",IF($Q65="","",ROUND(($Q65/$Q$10)*$R$10,2))) | S65: =IF($R65="","",ROUND($R65*$S$10,2)) | W65: =IF(OR(T65="",$T$10=""),"",(T65/$T$10)*$W$10) | X65: =IF(OR(U65="",$U$10=""),"",(U65/$U$10)*$X$10) | Y65: =IF(OR(V65="",$V$10=""),"",(V65/$V$10)*$Y$10) | Z65: =IF(COUNT($W65:$Y65)=0,"",IFERROR(ROUND((SUM($W65:$Y65)/SUM($W$10:$Y$10))*$Z$10,2),"")) | AA65: =IF($Z65="","",ROUND($Z65*$AA$10,2)) | AB65: =IF(ISERROR(IF($Z65="","",ROUND(SUM($M65,$S65,$AA65),2))),"",IF($Z65="","",ROUND(SUM($M65,$S65,$AA65),2))) | AC65: =IF(ISERROR(IF($Z65="","",VLOOKUP(AB65,NewTransmu,4,TRUE))),"",IF($Z65="","",VLOOKUP(AB65,NewTransmu,4,TRUE))) | AD65: =IF(ISERROR(IF(AC65="","",VLOOKUP(AC65,DESCRIPTORS,4,TRUE))),"",IF(AC65="","",VLOOKUP(AC65,DESCRIPTORS,4,TRUE))) | AQ65: =(T65/$T$10)*100 -> #DIV/0! | AR65: =(U65/$U$10)*100 -> #DIV/0! | AS65: =(V65/$V$10)*100 -> #DIV/0!
A66: 4 | B66: ='INPUT DATA'!P12 -> 0 | K66: =IF(COUNT($F66:$J66)=0,"",SUM($F66:$J66)) | L66: =IF(ISERROR(IF($K66="","",ROUND(($K66/$K$10)*$L$10,2))),"",IF($K66="","",ROUND(($K66/$K$10)*$L$10,2))) | M66: =IF($L66="","",ROUND($L66*$M$10,2)) | Q66: =IF(COUNT($N66:$P66)=0,"",SUM($N66:$P66)) | R66: =IF(ISERROR(IF($Q66="","",ROUND(($Q66/$Q$10)*$R$10,2))),"",IF($Q66="","",ROUND(($Q66/$Q$10)*$R$10,2))) | S66: =IF($R66="","",ROUND($R66*$S$10,2)) | W66: =IF(OR(T66="",$T$10=""),"",(T66/$T$10)*$W$10) | X66: =IF(OR(U66="",$U$10=""),"",(U66/$U$10)*$X$10) | Y66: =IF(OR(V66="",$V$10=""),"",(V66/$V$10)*$Y$10) | Z66: =IF(COUNT($W66:$Y66)=0,"",IFERROR(ROUND((SUM($W66:$Y66)/SUM($W$10:$Y$10))*$Z$10,2),"")) | AA66: =IF($Z66="","",ROUND($Z66*$AA$10,2)) | AB66: =IF(ISERROR(IF($Z66="","",ROUND(SUM($M66,$S66,$AA66),2))),"",IF($Z66="","",ROUND(SUM($M66,$S66,$AA66),2))) | AC66: =IF(ISERROR(IF($Z66="","",VLOOKUP(AB66,NewTransmu,4,TRUE))),"",IF($Z66="","",VLOOKUP(AB66,NewTransmu,4,TRUE))) | AD66: =IF(ISERROR(IF(AC66="","",VLOOKUP(AC66,DESCRIPTORS,4,TRUE))),"",IF(AC66="","",VLOOKUP(AC66,DESCRIPTORS,4,TRUE))) | AQ66: =(T66/$T$10)*100 -> #DIV/0! | AR66: =(U66/$U$10)*100 -> #DIV/0! | AS66: =(V66/$V$10)*100 -> #DIV/0!
A67: 5 | B67: ='INPUT DATA'!P13 -> 0 | K67: =IF(COUNT($F67:$J67)=0,"",SUM($F67:$J67)) | L67: =IF(ISERROR(IF($K67="","",ROUND(($K67/$K$10)*$L$10,2))),"",IF($K67="","",ROUND(($K67/$K$10)*$L$10,2))) | M67: =IF($L67="","",ROUND($L67*$M$10,2)) | Q67: =IF(COUNT($N67:$P67)=0,"",SUM($N67:$P67)) | R67: =IF(ISERROR(IF($Q67="","",ROUND(($Q67/$Q$10)*$R$10,2))),"",IF($Q67="","",ROUND(($Q67/$Q$10)*$R$10,2))) | S67: =IF($R67="","",ROUND($R67*$S$10,2)) | W67: =IF(OR(T67="",$T$10=""),"",(T67/$T$10)*$W$10) | X67: =IF(OR(U67="",$U$10=""),"",(U67/$U$10)*$X$10) | Y67: =IF(OR(V67="",$V$10=""),"",(V67/$V$10)*$Y$10) | Z67: =IF(COUNT($W67:$Y67)=0,"",IFERROR(ROUND((SUM($W67:$Y67)/SUM($W$10:$Y$10))*$Z$10,2),"")) | AA67: =IF($Z67="","",ROUND($Z67*$AA$10,2)) | AB67: =IF(ISERROR(IF($Z67="","",ROUND(SUM($M67,$S67,$AA67),2))),"",IF($Z67="","",ROUND(SUM($M67,$S67,$AA67),2))) | AC67: =IF(ISERROR(IF($Z67="","",VLOOKUP(AB67,NewTransmu,4,TRUE))),"",IF($Z67="","",VLOOKUP(AB67,NewTransmu,4,TRUE))) | AD67: =IF(ISERROR(IF(AC67="","",VLOOKUP(AC67,DESCRIPTORS,4,TRUE))),"",IF(AC67="","",VLOOKUP(AC67,DESCRIPTORS,4,TRUE))) | AQ67: =(T67/$T$10)*100 -> #DIV/0! | AR67: =(U67/$U$10)*100 -> #DIV/0! | AS67: =(V67/$V$10)*100 -> #DIV/0!
A68: 6 | B68: ='INPUT DATA'!P14 -> 0 | K68: =IF(COUNT($F68:$J68)=0,"",SUM($F68:$J68)) | L68: =IF(ISERROR(IF($K68="","",ROUND(($K68/$K$10)*$L$10,2))),"",IF($K68="","",ROUND(($K68/$K$10)*$L$10,2))) | M68: =IF($L68="","",ROUND($L68*$M$10,2)) | Q68: =IF(COUNT($N68:$P68)=0,"",SUM($N68:$P68)) | R68: =IF(ISERROR(IF($Q68="","",ROUND(($Q68/$Q$10)*$R$10,2))),"",IF($Q68="","",ROUND(($Q68/$Q$10)*$R$10,2))) | S68: =IF($R68="","",ROUND($R68*$S$10,2)) | W68: =IF(OR(T68="",$T$10=""),"",(T68/$T$10)*$W$10) | X68: =IF(OR(U68="",$U$10=""),"",(U68/$U$10)*$X$10) | Y68: =IF(OR(V68="",$V$10=""),"",(V68/$V$10)*$Y$10) | Z68: =IF(COUNT($W68:$Y68)=0,"",IFERROR(ROUND((SUM($W68:$Y68)/SUM($W$10:$Y$10))*$Z$10,2),"")) | AA68: =IF($Z68="","",ROUND($Z68*$AA$10,2)) | AB68: =IF(ISERROR(IF($Z68="","",ROUND(SUM($M68,$S68,$AA68),2))),"",IF($Z68="","",ROUND(SUM($M68,$S68,$AA68),2))) | AC68: =IF(ISERROR(IF($Z68="","",VLOOKUP(AB68,NewTransmu,4,TRUE))),"",IF($Z68="","",VLOOKUP(AB68,NewTransmu,4,TRUE))) | AD68: =IF(ISERROR(IF(AC68="","",VLOOKUP(AC68,DESCRIPTORS,4,TRUE))),"",IF(AC68="","",VLOOKUP(AC68,DESCRIPTORS,4,TRUE))) | AQ68: =(T68/$T$10)*100 -> #DIV/0! | AR68: =(U68/$U$10)*100 -> #DIV/0! | AS68: =(V68/$V$10)*100 -> #DIV/0!
A69: 7 | B69: ='INPUT DATA'!P15 -> 0 | K69: =IF(COUNT($F69:$J69)=0,"",SUM($F69:$J69)) | L69: =IF(ISERROR(IF($K69="","",ROUND(($K69/$K$10)*$L$10,2))),"",IF($K69="","",ROUND(($K69/$K$10)*$L$10,2))) | M69: =IF($L69="","",ROUND($L69*$M$10,2)) | Q69: =IF(COUNT($N69:$P69)=0,"",SUM($N69:$P69)) | R69: =IF(ISERROR(IF($Q69="","",ROUND(($Q69/$Q$10)*$R$10,2))),"",IF($Q69="","",ROUND(($Q69/$Q$10)*$R$10,2))) | S69: =IF($R69="","",ROUND($R69*$S$10,2)) | W69: =IF(OR(T69="",$T$10=""),"",(T69/$T$10)*$W$10) | X69: =IF(OR(U69="",$U$10=""),"",(U69/$U$10)*$X$10) | Y69: =IF(OR(V69="",$V$10=""),"",(V69/$V$10)*$Y$10) | Z69: =IF(COUNT($W69:$Y69)=0,"",IFERROR(ROUND((SUM($W69:$Y69)/SUM($W$10:$Y$10))*$Z$10,2),"")) | AA69: =IF($Z69="","",ROUND($Z69*$AA$10,2)) | AB69: =IF(ISERROR(IF($Z69="","",ROUND(SUM($M69,$S69,$AA69),2))),"",IF($Z69="","",ROUND(SUM($M69,$S69,$AA69),2))) | AC69: =IF(ISERROR(IF($Z69="","",VLOOKUP(AB69,NewTransmu,4,TRUE))),"",IF($Z69="","",VLOOKUP(AB69,NewTransmu,4,TRUE))) | AD69: =IF(ISERROR(IF(AC69="","",VLOOKUP(AC69,DESCRIPTORS,4,TRUE))),"",IF(AC69="","",VLOOKUP(AC69,DESCRIPTORS,4,TRUE))) | AQ69: =(T69/$T$10)*100 -> #DIV/0! | AR69: =(U69/$U$10)*100 -> #DIV/0! | AS69: =(V69/$V$10)*100 -> #DIV/0!
A70: 8 | B70: ='INPUT DATA'!P16 -> 0 | K70: =IF(COUNT($F70:$J70)=0,"",SUM($F70:$J70)) | L70: =IF(ISERROR(IF($K70="","",ROUND(($K70/$K$10)*$L$10,2))),"",IF($K70="","",ROUND(($K70/$K$10)*$L$10,2))) | M70: =IF($L70="","",ROUND($L70*$M$10,2)) | Q70: =IF(COUNT($N70:$P70)=0,"",SUM($N70:$P70)) | R70: =IF(ISERROR(IF($Q70="","",ROUND(($Q70/$Q$10)*$R$10,2))),"",IF($Q70="","",ROUND(($Q70/$Q$10)*$R$10,2))) | S70: =IF($R70="","",ROUND($R70*$S$10,2)) | W70: =IF(OR(T70="",$T$10=""),"",(T70/$T$10)*$W$10) | X70: =IF(OR(U70="",$U$10=""),"",(U70/$U$10)*$X$10) | Y70: =IF(OR(V70="",$V$10=""),"",(V70/$V$10)*$Y$10) | Z70: =IF(COUNT($W70:$Y70)=0,"",IFERROR(ROUND((SUM($W70:$Y70)/SUM($W$10:$Y$10))*$Z$10,2),"")) | AA70: =IF($Z70="","",ROUND($Z70*$AA$10,2)) | AB70: =IF(ISERROR(IF($Z70="","",ROUND(SUM($M70,$S70,$AA70),2))),"",IF($Z70="","",ROUND(SUM($M70,$S70,$AA70),2))) | AC70: =IF(ISERROR(IF($Z70="","",VLOOKUP(AB70,NewTransmu,4,TRUE))),"",IF($Z70="","",VLOOKUP(AB70,NewTransmu,4,TRUE))) | AD70: =IF(ISERROR(IF(AC70="","",VLOOKUP(AC70,DESCRIPTORS,4,TRUE))),"",IF(AC70="","",VLOOKUP(AC70,DESCRIPTORS,4,TRUE))) | AQ70: =(T70/$T$10)*100 -> #DIV/0! | AR70: =(U70/$U$10)*100 -> #DIV/0! | AS70: =(V70/$V$10)*100 -> #DIV/0!
A71: 9 | B71: ='INPUT DATA'!P17 -> 0 | K71: =IF(COUNT($F71:$J71)=0,"",SUM($F71:$J71)) | L71: =IF(ISERROR(IF($K71="","",ROUND(($K71/$K$10)*$L$10,2))),"",IF($K71="","",ROUND(($K71/$K$10)*$L$10,2))) | M71: =IF($L71="","",ROUND($L71*$M$10,2)) | Q71: =IF(COUNT($N71:$P71)=0,"",SUM($N71:$P71)) | R71: =IF(ISERROR(IF($Q71="","",ROUND(($Q71/$Q$10)*$R$10,2))),"",IF($Q71="","",ROUND(($Q71/$Q$10)*$R$10,2))) | S71: =IF($R71="","",ROUND($R71*$S$10,2)) | W71: =IF(OR(T71="",$T$10=""),"",(T71/$T$10)*$W$10) | X71: =IF(OR(U71="",$U$10=""),"",(U71/$U$10)*$X$10) | Y71: =IF(OR(V71="",$V$10=""),"",(V71/$V$10)*$Y$10) | Z71: =IF(COUNT($W71:$Y71)=0,"",IFERROR(ROUND((SUM($W71:$Y71)/SUM($W$10:$Y$10))*$Z$10,2),"")) | AA71: =IF($Z71="","",ROUND($Z71*$AA$10,2)) | AB71: =IF(ISERROR(IF($Z71="","",ROUND(SUM($M71,$S71,$AA71),2))),"",IF($Z71="","",ROUND(SUM($M71,$S71,$AA71),2))) | AC71: =IF(ISERROR(IF($Z71="","",VLOOKUP(AB71,NewTransmu,4,TRUE))),"",IF($Z71="","",VLOOKUP(AB71,NewTransmu,4,TRUE))) | AD71: =IF(ISERROR(IF(AC71="","",VLOOKUP(AC71,DESCRIPTORS,4,TRUE))),"",IF(AC71="","",VLOOKUP(AC71,DESCRIPTORS,4,TRUE))) | AQ71: =(T71/$T$10)*100 -> #DIV/0! | AR71: =(U71/$U$10)*100 -> #DIV/0! | AS71: =(V71/$V$10)*100 -> #DIV/0!
A72: 10 | B72: ='INPUT DATA'!P18 -> 0 | K72: =IF(COUNT($F72:$J72)=0,"",SUM($F72:$J72)) | L72: =IF(ISERROR(IF($K72="","",ROUND(($K72/$K$10)*$L$10,2))),"",IF($K72="","",ROUND(($K72/$K$10)*$L$10,2))) | M72: =IF($L72="","",ROUND($L72*$M$10,2)) | Q72: =IF(COUNT($N72:$P72)=0,"",SUM($N72:$P72)) | R72: =IF(ISERROR(IF($Q72="","",ROUND(($Q72/$Q$10)*$R$10,2))),"",IF($Q72="","",ROUND(($Q72/$Q$10)*$R$10,2))) | S72: =IF($R72="","",ROUND($R72*$S$10,2)) | W72: =IF(OR(T72="",$T$10=""),"",(T72/$T$10)*$W$10) | X72: =IF(OR(U72="",$U$10=""),"",(U72/$U$10)*$X$10) | Y72: =IF(OR(V72="",$V$10=""),"",(V72/$V$10)*$Y$10) | Z72: =IF(COUNT($W72:$Y72)=0,"",IFERROR(ROUND((SUM($W72:$Y72)/SUM($W$10:$Y$10))*$Z$10,2),"")) | AA72: =IF($Z72="","",ROUND($Z72*$AA$10,2)) | AB72: =IF(ISERROR(IF($Z72="","",ROUND(SUM($M72,$S72,$AA72),2))),"",IF($Z72="","",ROUND(SUM($M72,$S72,$AA72),2))) | AC72: =IF(ISERROR(IF($Z72="","",VLOOKUP(AB72,NewTransmu,4,TRUE))),"",IF($Z72="","",VLOOKUP(AB72,NewTransmu,4,TRUE))) | AD72: =IF(ISERROR(IF(AC72="","",VLOOKUP(AC72,DESCRIPTORS,4,TRUE))),"",IF(AC72="","",VLOOKUP(AC72,DESCRIPTORS,4,TRUE))) | AQ72: =(T72/$T$10)*100 -> #DIV/0! | AR72: =(U72/$U$10)*100 -> #DIV/0! | AS72: =(V72/$V$10)*100 -> #DIV/0!
A73: 11 | B73: ='INPUT DATA'!P19 -> 0 | K73: =IF(COUNT($F73:$J73)=0,"",SUM($F73:$J73)) | L73: =IF(ISERROR(IF($K73="","",ROUND(($K73/$K$10)*$L$10,2))),"",IF($K73="","",ROUND(($K73/$K$10)*$L$10,2))) | M73: =IF($L73="","",ROUND($L73*$M$10,2)) | Q73: =IF(COUNT($N73:$P73)=0,"",SUM($N73:$P73)) | R73: =IF(ISERROR(IF($Q73="","",ROUND(($Q73/$Q$10)*$R$10,2))),"",IF($Q73="","",ROUND(($Q73/$Q$10)*$R$10,2))) | S73: =IF($R73="","",ROUND($R73*$S$10,2)) | W73: =IF(OR(T73="",$T$10=""),"",(T73/$T$10)*$W$10) | X73: =IF(OR(U73="",$U$10=""),"",(U73/$U$10)*$X$10) | Y73: =IF(OR(V73="",$V$10=""),"",(V73/$V$10)*$Y$10) | Z73: =IF(COUNT($W73:$Y73)=0,"",IFERROR(ROUND((SUM($W73:$Y73)/SUM($W$10:$Y$10))*$Z$10,2),"")) | AA73: =IF($Z73="","",ROUND($Z73*$AA$10,2)) | AB73: =IF(ISERROR(IF($Z73="","",ROUND(SUM($M73,$S73,$AA73),2))),"",IF($Z73="","",ROUND(SUM($M73,$S73,$AA73),2))) | AC73: =IF(ISERROR(IF($Z73="","",VLOOKUP(AB73,NewTransmu,4,TRUE))),"",IF($Z73="","",VLOOKUP(AB73,NewTransmu,4,TRUE))) | AD73: =IF(ISERROR(IF(AC73="","",VLOOKUP(AC73,DESCRIPTORS,4,TRUE))),"",IF(AC73="","",VLOOKUP(AC73,DESCRIPTORS,4,TRUE))) | AQ73: =(T73/$T$10)*100 -> #DIV/0! | AR73: =(U73/$U$10)*100 -> #DIV/0! | AS73: =(V73/$V$10)*100 -> #DIV/0!
A74: 12 | B74: ='INPUT DATA'!P20 -> 0 | K74: =IF(COUNT($F74:$J74)=0,"",SUM($F74:$J74)) | L74: =IF(ISERROR(IF($K74="","",ROUND(($K74/$K$10)*$L$10,2))),"",IF($K74="","",ROUND(($K74/$K$10)*$L$10,2))) | M74: =IF($L74="","",ROUND($L74*$M$10,2)) | Q74: =IF(COUNT($N74:$P74)=0,"",SUM($N74:$P74)) | R74: =IF(ISERROR(IF($Q74="","",ROUND(($Q74/$Q$10)*$R$10,2))),"",IF($Q74="","",ROUND(($Q74/$Q$10)*$R$10,2))) | S74: =IF($R74="","",ROUND($R74*$S$10,2)) | W74: =IF(OR(T74="",$T$10=""),"",(T74/$T$10)*$W$10) | X74: =IF(OR(U74="",$U$10=""),"",(U74/$U$10)*$X$10) | Y74: =IF(OR(V74="",$V$10=""),"",(V74/$V$10)*$Y$10) | Z74: =IF(COUNT($W74:$Y74)=0,"",IFERROR(ROUND((SUM($W74:$Y74)/SUM($W$10:$Y$10))*$Z$10,2),"")) | AA74: =IF($Z74="","",ROUND($Z74*$AA$10,2)) | AB74: =IF(ISERROR(IF($Z74="","",ROUND(SUM($M74,$S74,$AA74),2))),"",IF($Z74="","",ROUND(SUM($M74,$S74,$AA74),2))) | AC74: =IF(ISERROR(IF($Z74="","",VLOOKUP(AB74,NewTransmu,4,TRUE))),"",IF($Z74="","",VLOOKUP(AB74,NewTransmu,4,TRUE))) | AD74: =IF(ISERROR(IF(AC74="","",VLOOKUP(AC74,DESCRIPTORS,4,TRUE))),"",IF(AC74="","",VLOOKUP(AC74,DESCRIPTORS,4,TRUE))) | AQ74: =(T74/$T$10)*100 -> #DIV/0! | AR74: =(U74/$U$10)*100 -> #DIV/0! | AS74: =(V74/$V$10)*100 -> #DIV/0!
... A112: 50 | B112: ='INPUT DATA'!P58 -> 0 | K112: =IF(COUNT($F112:$J112)=0,"",SUM($F112:$J112)) | L112: =IF(ISERROR(IF($K112="","",ROUND(($K112/$K$10)*$L$10,2))),"",IF($K112="","",ROUND(($K112/$K$10)*$L$10,2))) | M112: =IF($L112="","",ROUND($L112*$M$10,2)) | Q112: =IF(COUNT($N112:$P112)=0,"",SUM($N112:$P112)) | R112: =IF(ISERROR(IF($Q112="","",ROUND(($Q112/$Q$10)*$R$10,2))),"",IF($Q112="","",ROUND(($Q112/$Q$10)*$R$10,2))) | S112: =IF($R112="","",ROUND($R112*$S$10,2)) | W112: =IF(OR(T112="",$T$10=""),"",(T112/$T$10)*$W$10) | X112: =IF(OR(U112="",$U$10=""),"",(U112/$U$10)*$X$10) | Y112: =IF(OR(V112="",$V$10=""),"",(V112/$V$10)*$Y$10) | Z112: =IF(COUNT($W112:$Y112)=0,"",IFERROR(ROUND((SUM($W112:$Y112)/SUM($W$10:$Y$10))*$Z$10,2),"")) | AA112: =IF($Z112="","",ROUND($Z112*$AA$10,2)) | AB112: =IF(ISERROR(IF($Z112="","",ROUND(SUM($M112,$S112,$AA112),2))),"",IF($Z112="","",ROUND(SUM($M112,$S112,$AA112),2))) | AC112: =IF(ISERROR(IF($Z112="","",VLOOKUP(AB112,NewTransmu,4,TRUE))),"",IF($Z112="","",VLOOKUP(AB112,NewTransmu,4,TRUE))) | AD112: =IF(ISERROR(IF(AC112="","",VLOOKUP(AC112,DESCRIPTORS,4,TRUE))),"",IF(AC112="","",VLOOKUP(AC112,DESCRIPTORS,4,TRUE))) | AQ112: =(T112/$T$10)*100 -> #DIV/0! | AR112: =(U112/$U$10)*100 -> #DIV/0! | AS112: =(V112/$V$10)*100 -> #DIV/0!

Sheet PEH_T1
A1: Class Record
B4: REGION | G4: ='INPUT DATA'!E8 -> X | I4: DIVISION | L4: ='INPUT DATA'!E9 -> EDUCATORS FILES
B5: SCHOOL NAME | G5: ='INPUT DATA'!E10 -> EFILES NATIONAL HIGH SCHOOL | Q5: SCHOOL ID | S5: ='INPUT DATA'!E11 -> 123456 | V5: SCHOOL YEAR | AB5: ='INPUT DATA'!E12 -> 2026-2027
A7: TERM 1 | F7: GRADE & SECTION: | J7: ='INPUT DATA'!E14 -> VI - MASIPAG | N7: TEACHER: | Q7: ='INPUT DATA'!E17 -> SAMUEL A. SILVERIO | Z7: SUBJECT: | AB7: PE & HEALTH
B8: LEARNERS' NAMES | F8: WRITTEN / ORAL WORKS (20%) | N8: PRODUCT / PERFORMANCE TASKS (60%) | T8: SUMMATIVE TESTS AND TERM EXAMINATIONS (20%) | AB8: Initial Grade | AC8: TERM GRADE | AD8: DESCRIPTOR
F9: 1 | G9: 2 | H9: 3 | I9: 4 | J9: 5 | K9: Total | L9: PS | M9: WS | N9: 1 | O9: 2 | P9: 3 | Q9: Total | R9: PS | S9: WS | T9: ST1 | U9: ST2 | V9: TE | W9: WS ST1 (30%) | X9: WS ST2 (30%) | Y9: WS TE (40%) | Z9: PS ST&TE | AA9: WS ST&TE
B10: HIGHEST POSSIBLE SCORE | K10: =IF(COUNT($F10:$J10)=0,"",SUM($F10:$J10)) | L10: 100 | M10: 0.2 | Q10: =IF(COUNT($N10:$P10)=0,"",SUM($N10:$P10)) | R10: 100 | S10: 0.6 | W10: 30 | X10: 30 | Y10: 40 | Z10: 100 | AA10: 0.2
B11: MALE | AS11: ST1 | AT11: ST2 | AU11: TE
A12: 1 | B12: ='INPUT DATA'!J9 -> 0 | K12: =IF(COUNT($F12:$J12)=0,"",SUM($F12:$J12)) | L12: =IF(ISERROR(IF($K12="","",ROUND(($K12/$K$10)*$L$10,2))),"",IF($K12="","",ROUND(($K12/$K$10)*$L$10,2))) | M12: =IF($L12="","",ROUND($L12*$M$10,2)) | Q12: =IF(COUNT($N12:$P12)=0,"",SUM($N12:$P12)) | R12: =IF(ISERROR(IF($Q12="","",ROUND(($Q12/$Q$10)*$R$10,2))),"",IF($Q12="","",ROUND(($Q12/$Q$10)*$R$10,2))) | S12: =IF($R12="","",ROUND($R12*$S$10,2)) | W12: =IF(OR(T12="",$T$10=""),"",(T12/$T$10)*$W$10) | X12: =IF(OR(U12="",$U$10=""),"",(U12/$U$10)*$X$10) | Y12: =IF(OR(V12="",$V$10=""),"",(V12/$V$10)*$Y$10) | Z12: =IF(COUNT($W12:$Y12)=0,"",IFERROR(ROUND((SUM($W12:$Y12)/SUM($W$10:$Y$10))*$Z$10,2),"")) | AA12: =IF($Z12="","",ROUND($Z12*$AA$10,2)) | AB12: =IF(ISERROR(IF($Z12="","",ROUND(SUM($M12,$S12,$AA12),2))),"",IF($Z12="","",ROUND(SUM($M12,$S12,$AA12),2))) | AC12: =IF(ISERROR(IF($Z12="","",VLOOKUP(AB12,NewTransmu,4,TRUE))),"",IF($Z12="","",VLOOKUP(AB12,NewTransmu,4,TRUE))) | AD12: =IF(ISERROR(IF(AC12="","",VLOOKUP(AC12,DESCRIPTORS,4,TRUE))),"",IF(AC12="","",VLOOKUP(AC12,DESCRIPTORS,4,TRUE))) | AS12: =(T12/$T$10)*100 -> #DIV/0! | AT12: =(U12/$U$10)*100 -> #DIV/0! | AU12: =(V12/$V$10)*100 -> #DIV/0!
A13: 2 | B13: ='INPUT DATA'!J10 -> 0 | K13: =IF(COUNT($F13:$J13)=0,"",SUM($F13:$J13)) | L13: =IF(ISERROR(IF($K13="","",ROUND(($K13/$K$10)*$L$10,2))),"",IF($K13="","",ROUND(($K13/$K$10)*$L$10,2))) | M13: =IF($L13="","",ROUND($L13*$M$10,2)) | Q13: =IF(COUNT($N13:$P13)=0,"",SUM($N13:$P13)) | R13: =IF(ISERROR(IF($Q13="","",ROUND(($Q13/$Q$10)*$R$10,2))),"",IF($Q13="","",ROUND(($Q13/$Q$10)*$R$10,2))) | S13: =IF($R13="","",ROUND($R13*$S$10,2)) | W13: =IF(OR(T13="",$T$10=""),"",(T13/$T$10)*$W$10) | X13: =IF(OR(U13="",$U$10=""),"",(U13/$U$10)*$X$10) | Y13: =IF(OR(V13="",$V$10=""),"",(V13/$V$10)*$Y$10) | Z13: =IF(COUNT($W13:$Y13)=0,"",IFERROR(ROUND((SUM($W13:$Y13)/SUM($W$10:$Y$10))*$Z$10,2),"")) | AA13: =IF($Z13="","",ROUND($Z13*$AA$10,2)) | AB13: =IF(ISERROR(IF($Z13="","",ROUND(SUM($M13,$S13,$AA13),2))),"",IF($Z13="","",ROUND(SUM($M13,$S13,$AA13),2))) | AC13: =IF(ISERROR(IF($Z13="","",VLOOKUP(AB13,NewTransmu,4,TRUE))),"",IF($Z13="","",VLOOKUP(AB13,NewTransmu,4,TRUE))) | AD13: =IF(ISERROR(IF(AC13="","",VLOOKUP(AC13,DESCRIPTORS,4,TRUE))),"",IF(AC13="","",VLOOKUP(AC13,DESCRIPTORS,4,TRUE))) | AS13: =(T13/$T$10)*100 -> #DIV/0! | AT13: =(U13/$U$10)*100 -> #DIV/0! | AU13: =(V13/$V$10)*100 -> #DIV/0!
A14: 3 | B14: ='INPUT DATA'!J11 -> 0 | K14: =IF(COUNT($F14:$J14)=0,"",SUM($F14:$J14)) | L14: =IF(ISERROR(IF($K14="","",ROUND(($K14/$K$10)*$L$10,2))),"",IF($K14="","",ROUND(($K14/$K$10)*$L$10,2))) | M14: =IF($L14="","",ROUND($L14*$M$10,2)) | Q14: =IF(COUNT($N14:$P14)=0,"",SUM($N14:$P14)) | R14: =IF(ISERROR(IF($Q14="","",ROUND(($Q14/$Q$10)*$R$10,2))),"",IF($Q14="","",ROUND(($Q14/$Q$10)*$R$10,2))) | S14: =IF($R14="","",ROUND($R14*$S$10,2)) | W14: =IF(OR(T14="",$T$10=""),"",(T14/$T$10)*$W$10) | X14: =IF(OR(U14="",$U$10=""),"",(U14/$U$10)*$X$10) | Y14: =IF(OR(V14="",$V$10=""),"",(V14/$V$10)*$Y$10) | Z14: =IF(COUNT($W14:$Y14)=0,"",IFERROR(ROUND((SUM($W14:$Y14)/SUM($W$10:$Y$10))*$Z$10,2),"")) | AA14: =IF($Z14="","",ROUND($Z14*$AA$10,2)) | AB14: =IF(ISERROR(IF($Z14="","",ROUND(SUM($M14,$S14,$AA14),2))),"",IF($Z14="","",ROUND(SUM($M14,$S14,$AA14),2))) | AC14: =IF(ISERROR(IF($Z14="","",VLOOKUP(AB14,NewTransmu,4,TRUE))),"",IF($Z14="","",VLOOKUP(AB14,NewTransmu,4,TRUE))) | AD14: =IF(ISERROR(IF(AC14="","",VLOOKUP(AC14,DESCRIPTORS,4,TRUE))),"",IF(AC14="","",VLOOKUP(AC14,DESCRIPTORS,4,TRUE))) | AS14: =(T14/$T$10)*100 -> #DIV/0! | AT14: =(U14/$U$10)*100 -> #DIV/0! | AU14: =(V14/$V$10)*100 -> #DIV/0!
A15: 4 | B15: ='INPUT DATA'!J12 -> 0 | K15: =IF(COUNT($F15:$J15)=0,"",SUM($F15:$J15)) | L15: =IF(ISERROR(IF($K15="","",ROUND(($K15/$K$10)*$L$10,2))),"",IF($K15="","",ROUND(($K15/$K$10)*$L$10,2))) | M15: =IF($L15="","",ROUND($L15*$M$10,2)) | Q15: =IF(COUNT($N15:$P15)=0,"",SUM($N15:$P15)) | R15: =IF(ISERROR(IF($Q15="","",ROUND(($Q15/$Q$10)*$R$10,2))),"",IF($Q15="","",ROUND(($Q15/$Q$10)*$R$10,2))) | S15: =IF($R15="","",ROUND($R15*$S$10,2)) | W15: =IF(OR(T15="",$T$10=""),"",(T15/$T$10)*$W$10) | X15: =IF(OR(U15="",$U$10=""),"",(U15/$U$10)*$X$10) | Y15: =IF(OR(V15="",$V$10=""),"",(V15/$V$10)*$Y$10) | Z15: =IF(COUNT($W15:$Y15)=0,"",IFERROR(ROUND((SUM($W15:$Y15)/SUM($W$10:$Y$10))*$Z$10,2),"")) | AA15: =IF($Z15="","",ROUND($Z15*$AA$10,2)) | AB15: =IF(ISERROR(IF($Z15="","",ROUND(SUM($M15,$S15,$AA15),2))),"",IF($Z15="","",ROUND(SUM($M15,$S15,$AA15),2))) | AC15: =IF(ISERROR(IF($Z15="","",VLOOKUP(AB15,NewTransmu,4,TRUE))),"",IF($Z15="","",VLOOKUP(AB15,NewTransmu,4,TRUE))) | AD15: =IF(ISERROR(IF(AC15="","",VLOOKUP(AC15,DESCRIPTORS,4,TRUE))),"",IF(AC15="","",VLOOKUP(AC15,DESCRIPTORS,4,TRUE))) | AS15: =(T15/$T$10)*100 -> #DIV/0! | AT15: =(U15/$U$10)*100 -> #DIV/0! | AU15: =(V15/$V$10)*100 -> #DIV/0!
A16: 5 | B16: ='INPUT DATA'!J13 -> 0 | K16: =IF(COUNT($F16:$J16)=0,"",SUM($F16:$J16)) | L16: =IF(ISERROR(IF($K16="","",ROUND(($K16/$K$10)*$L$10,2))),"",IF($K16="","",ROUND(($K16/$K$10)*$L$10,2))) | M16: =IF($L16="","",ROUND($L16*$M$10,2)) | Q16: =IF(COUNT($N16:$P16)=0,"",SUM($N16:$P16)) | R16: =IF(ISERROR(IF($Q16="","",ROUND(($Q16/$Q$10)*$R$10,2))),"",IF($Q16="","",ROUND(($Q16/$Q$10)*$R$10,2))) | S16: =IF($R16="","",ROUND($R16*$S$10,2)) | W16: =IF(OR(T16="",$T$10=""),"",(T16/$T$10)*$W$10) | X16: =IF(OR(U16="",$U$10=""),"",(U16/$U$10)*$X$10) | Y16: =IF(OR(V16="",$V$10=""),"",(V16/$V$10)*$Y$10) | Z16: =IF(COUNT($W16:$Y16)=0,"",IFERROR(ROUND((SUM($W16:$Y16)/SUM($W$10:$Y$10))*$Z$10,2),"")) | AA16: =IF($Z16="","",ROUND($Z16*$AA$10,2)) | AB16: =IF(ISERROR(IF($Z16="","",ROUND(SUM($M16,$S16,$AA16),2))),"",IF($Z16="","",ROUND(SUM($M16,$S16,$AA16),2))) | AC16: =IF(ISERROR(IF($Z16="","",VLOOKUP(AB16,NewTransmu,4,TRUE))),"",IF($Z16="","",VLOOKUP(AB16,NewTransmu,4,TRUE))) | AD16: =IF(ISERROR(IF(AC16="","",VLOOKUP(AC16,DESCRIPTORS,4,TRUE))),"",IF(AC16="","",VLOOKUP(AC16,DESCRIPTORS,4,TRUE))) | AS16: =(T16/$T$10)*100 -> #DIV/0! | AT16: =(U16/$U$10)*100 -> #DIV/0! | AU16: =(V16/$V$10)*100 -> #DIV/0!
A17: 6 | B17: ='INPUT DATA'!J14 -> 0 | K17: =IF(COUNT($F17:$J17)=0,"",SUM($F17:$J17)) | L17: =IF(ISERROR(IF($K17="","",ROUND(($K17/$K$10)*$L$10,2))),"",IF($K17="","",ROUND(($K17/$K$10)*$L$10,2))) | M17: =IF($L17="","",ROUND($L17*$M$10,2)) | Q17: =IF(COUNT($N17:$P17)=0,"",SUM($N17:$P17)) | R17: =IF(ISERROR(IF($Q17="","",ROUND(($Q17/$Q$10)*$R$10,2))),"",IF($Q17="","",ROUND(($Q17/$Q$10)*$R$10,2))) | S17: =IF($R17="","",ROUND($R17*$S$10,2)) | W17: =IF(OR(T17="",$T$10=""),"",(T17/$T$10)*$W$10) | X17: =IF(OR(U17="",$U$10=""),"",(U17/$U$10)*$X$10) | Y17: =IF(OR(V17="",$V$10=""),"",(V17/$V$10)*$Y$10) | Z17: =IF(COUNT($W17:$Y17)=0,"",IFERROR(ROUND((SUM($W17:$Y17)/SUM($W$10:$Y$10))*$Z$10,2),"")) | AA17: =IF($Z17="","",ROUND($Z17*$AA$10,2)) | AB17: =IF(ISERROR(IF($Z17="","",ROUND(SUM($M17,$S17,$AA17),2))),"",IF($Z17="","",ROUND(SUM($M17,$S17,$AA17),2))) | AC17: =IF(ISERROR(IF($Z17="","",VLOOKUP(AB17,NewTransmu,4,TRUE))),"",IF($Z17="","",VLOOKUP(AB17,NewTransmu,4,TRUE))) | AD17: =IF(ISERROR(IF(AC17="","",VLOOKUP(AC17,DESCRIPTORS,4,TRUE))),"",IF(AC17="","",VLOOKUP(AC17,DESCRIPTORS,4,TRUE))) | AS17: =(T17/$T$10)*100 -> #DIV/0! | AT17: =(U17/$U$10)*100 -> #DIV/0! | AU17: =(V17/$V$10)*100 -> #DIV/0!
A18: 7 | B18: ='INPUT DATA'!J15 -> 0 | K18: =IF(COUNT($F18:$J18)=0,"",SUM($F18:$J18)) | L18: =IF(ISERROR(IF($K18="","",ROUND(($K18/$K$10)*$L$10,2))),"",IF($K18="","",ROUND(($K18/$K$10)*$L$10,2))) | M18: =IF($L18="","",ROUND($L18*$M$10,2)) | Q18: =IF(COUNT($N18:$P18)=0,"",SUM($N18:$P18)) | R18: =IF(ISERROR(IF($Q18="","",ROUND(($Q18/$Q$10)*$R$10,2))),"",IF($Q18="","",ROUND(($Q18/$Q$10)*$R$10,2))) | S18: =IF($R18="","",ROUND($R18*$S$10,2)) | W18: =IF(OR(T18="",$T$10=""),"",(T18/$T$10)*$W$10) | X18: =IF(OR(U18="",$U$10=""),"",(U18/$U$10)*$X$10) | Y18: =IF(OR(V18="",$V$10=""),"",(V18/$V$10)*$Y$10) | Z18: =IF(COUNT($W18:$Y18)=0,"",IFERROR(ROUND((SUM($W18:$Y18)/SUM($W$10:$Y$10))*$Z$10,2),"")) | AA18: =IF($Z18="","",ROUND($Z18*$AA$10,2)) | AB18: =IF(ISERROR(IF($Z18="","",ROUND(SUM($M18,$S18,$AA18),2))),"",IF($Z18="","",ROUND(SUM($M18,$S18,$AA18),2))) | AC18: =IF(ISERROR(IF($Z18="","",VLOOKUP(AB18,NewTransmu,4,TRUE))),"",IF($Z18="","",VLOOKUP(AB18,NewTransmu,4,TRUE))) | AD18: =IF(ISERROR(IF(AC18="","",VLOOKUP(AC18,DESCRIPTORS,4,TRUE))),"",IF(AC18="","",VLOOKUP(AC18,DESCRIPTORS,4,TRUE))) | AS18: =(T18/$T$10)*100 -> #DIV/0! | AT18: =(U18/$U$10)*100 -> #DIV/0! | AU18: =(V18/$V$10)*100 -> #DIV/0!
A19: 8 | B19: ='INPUT DATA'!J16 -> 0 | K19: =IF(COUNT($F19:$J19)=0,"",SUM($F19:$J19)) | L19: =IF(ISERROR(IF($K19="","",ROUND(($K19/$K$10)*$L$10,2))),"",IF($K19="","",ROUND(($K19/$K$10)*$L$10,2))) | M19: =IF($L19="","",ROUND($L19*$M$10,2)) | Q19: =IF(COUNT($N19:$P19)=0,"",SUM($N19:$P19)) | R19: =IF(ISERROR(IF($Q19="","",ROUND(($Q19/$Q$10)*$R$10,2))),"",IF($Q19="","",ROUND(($Q19/$Q$10)*$R$10,2))) | S19: =IF($R19="","",ROUND($R19*$S$10,2)) | W19: =IF(OR(T19="",$T$10=""),"",(T19/$T$10)*$W$10) | X19: =IF(OR(U19="",$U$10=""),"",(U19/$U$10)*$X$10) | Y19: =IF(OR(V19="",$V$10=""),"",(V19/$V$10)*$Y$10) | Z19: =IF(COUNT($W19:$Y19)=0,"",IFERROR(ROUND((SUM($W19:$Y19)/SUM($W$10:$Y$10))*$Z$10,2),"")) | AA19: =IF($Z19="","",ROUND($Z19*$AA$10,2)) | AB19: =IF(ISERROR(IF($Z19="","",ROUND(SUM($M19,$S19,$AA19),2))),"",IF($Z19="","",ROUND(SUM($M19,$S19,$AA19),2))) | AC19: =IF(ISERROR(IF($Z19="","",VLOOKUP(AB19,NewTransmu,4,TRUE))),"",IF($Z19="","",VLOOKUP(AB19,NewTransmu,4,TRUE))) | AD19: =IF(ISERROR(IF(AC19="","",VLOOKUP(AC19,DESCRIPTORS,4,TRUE))),"",IF(AC19="","",VLOOKUP(AC19,DESCRIPTORS,4,TRUE))) | AS19: =(T19/$T$10)*100 -> #DIV/0! | AT19: =(U19/$U$10)*100 -> #DIV/0! | AU19: =(V19/$V$10)*100 -> #DIV/0!
A20: 9 | B20: ='INPUT DATA'!J17 -> 0 | K20: =IF(COUNT($F20:$J20)=0,"",SUM($F20:$J20)) | L20: =IF(ISERROR(IF($K20="","",ROUND(($K20/$K$10)*$L$10,2))),"",IF($K20="","",ROUND(($K20/$K$10)*$L$10,2))) | M20: =IF($L20="","",ROUND($L20*$M$10,2)) | Q20: =IF(COUNT($N20:$P20)=0,"",SUM($N20:$P20)) | R20: =IF(ISERROR(IF($Q20="","",ROUND(($Q20/$Q$10)*$R$10,2))),"",IF($Q20="","",ROUND(($Q20/$Q$10)*$R$10,2))) | S20: =IF($R20="","",ROUND($R20*$S$10,2)) | W20: =IF(OR(T20="",$T$10=""),"",(T20/$T$10)*$W$10) | X20: =IF(OR(U20="",$U$10=""),"",(U20/$U$10)*$X$10) | Y20: =IF(OR(V20="",$V$10=""),"",(V20/$V$10)*$Y$10) | Z20: =IF(COUNT($W20:$Y20)=0,"",IFERROR(ROUND((SUM($W20:$Y20)/SUM($W$10:$Y$10))*$Z$10,2),"")) | AA20: =IF($Z20="","",ROUND($Z20*$AA$10,2)) | AB20: =IF(ISERROR(IF($Z20="","",ROUND(SUM($M20,$S20,$AA20),2))),"",IF($Z20="","",ROUND(SUM($M20,$S20,$AA20),2))) | AC20: =IF(ISERROR(IF($Z20="","",VLOOKUP(AB20,NewTransmu,4,TRUE))),"",IF($Z20="","",VLOOKUP(AB20,NewTransmu,4,TRUE))) | AD20: =IF(ISERROR(IF(AC20="","",VLOOKUP(AC20,DESCRIPTORS,4,TRUE))),"",IF(AC20="","",VLOOKUP(AC20,DESCRIPTORS,4,TRUE))) | AS20: =(T20/$T$10)*100 -> #DIV/0! | AT20: =(U20/$U$10)*100 -> #DIV/0! | AU20: =(V20/$V$10)*100 -> #DIV/0!
A21: 10 | B21: ='INPUT DATA'!J18 -> 0 | K21: =IF(COUNT($F21:$J21)=0,"",SUM($F21:$J21)) | L21: =IF(ISERROR(IF($K21="","",ROUND(($K21/$K$10)*$L$10,2))),"",IF($K21="","",ROUND(($K21/$K$10)*$L$10,2))) | M21: =IF($L21="","",ROUND($L21*$M$10,2)) | Q21: =IF(COUNT($N21:$P21)=0,"",SUM($N21:$P21)) | R21: =IF(ISERROR(IF($Q21="","",ROUND(($Q21/$Q$10)*$R$10,2))),"",IF($Q21="","",ROUND(($Q21/$Q$10)*$R$10,2))) | S21: =IF($R21="","",ROUND($R21*$S$10,2)) | W21: =IF(OR(T21="",$T$10=""),"",(T21/$T$10)*$W$10) | X21: =IF(OR(U21="",$U$10=""),"",(U21/$U$10)*$X$10) | Y21: =IF(OR(V21="",$V$10=""),"",(V21/$V$10)*$Y$10) | Z21: =IF(COUNT($W21:$Y21)=0,"",IFERROR(ROUND((SUM($W21:$Y21)/SUM($W$10:$Y$10))*$Z$10,2),"")) | AA21: =IF($Z21="","",ROUND($Z21*$AA$10,2)) | AB21: =IF(ISERROR(IF($Z21="","",ROUND(SUM($M21,$S21,$AA21),2))),"",IF($Z21="","",ROUND(SUM($M21,$S21,$AA21),2))) | AC21: =IF(ISERROR(IF($Z21="","",VLOOKUP(AB21,NewTransmu,4,TRUE))),"",IF($Z21="","",VLOOKUP(AB21,NewTransmu,4,TRUE))) | AD21: =IF(ISERROR(IF(AC21="","",VLOOKUP(AC21,DESCRIPTORS,4,TRUE))),"",IF(AC21="","",VLOOKUP(AC21,DESCRIPTORS,4,TRUE))) | AS21: =(T21/$T$10)*100 -> #DIV/0! | AT21: =(U21/$U$10)*100 -> #DIV/0! | AU21: =(V21/$V$10)*100 -> #DIV/0!
A22: 11 | B22: ='INPUT DATA'!J19 -> 0 | K22: =IF(COUNT($F22:$J22)=0,"",SUM($F22:$J22)) | L22: =IF(ISERROR(IF($K22="","",ROUND(($K22/$K$10)*$L$10,2))),"",IF($K22="","",ROUND(($K22/$K$10)*$L$10,2))) | M22: =IF($L22="","",ROUND($L22*$M$10,2)) | Q22: =IF(COUNT($N22:$P22)=0,"",SUM($N22:$P22)) | R22: =IF(ISERROR(IF($Q22="","",ROUND(($Q22/$Q$10)*$R$10,2))),"",IF($Q22="","",ROUND(($Q22/$Q$10)*$R$10,2))) | S22: =IF($R22="","",ROUND($R22*$S$10,2)) | W22: =IF(OR(T22="",$T$10=""),"",(T22/$T$10)*$W$10) | X22: =IF(OR(U22="",$U$10=""),"",(U22/$U$10)*$X$10) | Y22: =IF(OR(V22="",$V$10=""),"",(V22/$V$10)*$Y$10) | Z22: =IF(COUNT($W22:$Y22)=0,"",IFERROR(ROUND((SUM($W22:$Y22)/SUM($W$10:$Y$10))*$Z$10,2),"")) | AA22: =IF($Z22="","",ROUND($Z22*$AA$10,2)) | AB22: =IF(ISERROR(IF($Z22="","",ROUND(SUM($M22,$S22,$AA22),2))),"",IF($Z22="","",ROUND(SUM($M22,$S22,$AA22),2))) | AC22: =IF(ISERROR(IF($Z22="","",VLOOKUP(AB22,NewTransmu,4,TRUE))),"",IF($Z22="","",VLOOKUP(AB22,NewTransmu,4,TRUE))) | AD22: =IF(ISERROR(IF(AC22="","",VLOOKUP(AC22,DESCRIPTORS,4,TRUE))),"",IF(AC22="","",VLOOKUP(AC22,DESCRIPTORS,4,TRUE))) | AS22: =(T22/$T$10)*100 -> #DIV/0! | AT22: =(U22/$U$10)*100 -> #DIV/0! | AU22: =(V22/$V$10)*100 -> #DIV/0!
A23: 12 | B23: ='INPUT DATA'!J20 -> 0 | K23: =IF(COUNT($F23:$J23)=0,"",SUM($F23:$J23)) | L23: =IF(ISERROR(IF($K23="","",ROUND(($K23/$K$10)*$L$10,2))),"",IF($K23="","",ROUND(($K23/$K$10)*$L$10,2))) | M23: =IF($L23="","",ROUND($L23*$M$10,2)) | Q23: =IF(COUNT($N23:$P23)=0,"",SUM($N23:$P23)) | R23: =IF(ISERROR(IF($Q23="","",ROUND(($Q23/$Q$10)*$R$10,2))),"",IF($Q23="","",ROUND(($Q23/$Q$10)*$R$10,2))) | S23: =IF($R23="","",ROUND($R23*$S$10,2)) | W23: =IF(OR(T23="",$T$10=""),"",(T23/$T$10)*$W$10) | X23: =IF(OR(U23="",$U$10=""),"",(U23/$U$10)*$X$10) | Y23: =IF(OR(V23="",$V$10=""),"",(V23/$V$10)*$Y$10) | Z23: =IF(COUNT($W23:$Y23)=0,"",IFERROR(ROUND((SUM($W23:$Y23)/SUM($W$10:$Y$10))*$Z$10,2),"")) | AA23: =IF($Z23="","",ROUND($Z23*$AA$10,2)) | AB23: =IF(ISERROR(IF($Z23="","",ROUND(SUM($M23,$S23,$AA23),2))),"",IF($Z23="","",ROUND(SUM($M23,$S23,$AA23),2))) | AC23: =IF(ISERROR(IF($Z23="","",VLOOKUP(AB23,NewTransmu,4,TRUE))),"",IF($Z23="","",VLOOKUP(AB23,NewTransmu,4,TRUE))) | AD23: =IF(ISERROR(IF(AC23="","",VLOOKUP(AC23,DESCRIPTORS,4,TRUE))),"",IF(AC23="","",VLOOKUP(AC23,DESCRIPTORS,4,TRUE))) | AS23: =(T23/$T$10)*100 -> #DIV/0! | AT23: =(U23/$U$10)*100 -> #DIV/0! | AU23: =(V23/$V$10)*100 -> #DIV/0!
... A61: 50 | B61: ='INPUT DATA'!J58 -> 0 | K61: =IF(COUNT($F61:$J61)=0,"",SUM($F61:$J61)) | L61: =IF(ISERROR(IF($K61="","",ROUND(($K61/$K$10)*$L$10,2))),"",IF($K61="","",ROUND(($K61/$K$10)*$L$10,2))) | M61: =IF($L61="","",ROUND($L61*$M$10,2)) | Q61: =IF(COUNT($N61:$P61)=0,"",SUM($N61:$P61)) | R61: =IF(ISERROR(IF($Q61="","",ROUND(($Q61/$Q$10)*$R$10,2))),"",IF($Q61="","",ROUND(($Q61/$Q$10)*$R$10,2))) | S61: =IF($R61="","",ROUND($R61*$S$10,2)) | W61: =IF(OR(T61="",$T$10=""),"",(T61/$T$10)*$W$10) | X61: =IF(OR(U61="",$U$10=""),"",(U61/$U$10)*$X$10) | Y61: =IF(OR(V61="",$V$10=""),"",(V61/$V$10)*$Y$10) | Z61: =IF(COUNT($W61:$Y61)=0,"",IFERROR(ROUND((SUM($W61:$Y61)/SUM($W$10:$Y$10))*$Z$10,2),"")) | AA61: =IF($Z61="","",ROUND($Z61*$AA$10,2)) | AB61: =IF(ISERROR(IF($Z61="","",ROUND(SUM($M61,$S61,$AA61),2))),"",IF($Z61="","",ROUND(SUM($M61,$S61,$AA61),2))) | AC61: =IF(ISERROR(IF($Z61="","",VLOOKUP(AB61,NewTransmu,4,TRUE))),"",IF($Z61="","",VLOOKUP(AB61,NewTransmu,4,TRUE))) | AD61: =IF(ISERROR(IF(AC61="","",VLOOKUP(AC61,DESCRIPTORS,4,TRUE))),"",IF(AC61="","",VLOOKUP(AC61,DESCRIPTORS,4,TRUE))) | AS61: =(T61/$T$10)*100 -> #DIV/0! | AT61: =(U61/$U$10)*100 -> #DIV/0! | AU61: =(V61/$V$10)*100 -> #DIV/0!
B62: FEMALE | AS62: =(T62/$T$10)*100 -> #DIV/0! | AT62: =(U62/$U$10)*100 -> #DIV/0! | AU62: =(V62/$V$10)*100 -> #DIV/0!
A63: 1 | B63: ='INPUT DATA'!P9 -> 0 | K63: =IF(COUNT($F63:$J63)=0,"",SUM($F63:$J63)) | L63: =IF(ISERROR(IF($K63="","",ROUND(($K63/$K$10)*$L$10,2))),"",IF($K63="","",ROUND(($K63/$K$10)*$L$10,2))) | M63: =IF($L63="","",ROUND($L63*$M$10,2)) | Q63: =IF(COUNT($N63:$P63)=0,"",SUM($N63:$P63)) | R63: =IF(ISERROR(IF($Q63="","",ROUND(($Q63/$Q$10)*$R$10,2))),"",IF($Q63="","",ROUND(($Q63/$Q$10)*$R$10,2))) | S63: =IF($R63="","",ROUND($R63*$S$10,2)) | W63: =IF(OR(T63="",$T$10=""),"",(T63/$T$10)*$W$10) | X63: =IF(OR(U63="",$U$10=""),"",(U63/$U$10)*$X$10) | Y63: =IF(OR(V63="",$V$10=""),"",(V63/$V$10)*$Y$10) | Z63: =IF(COUNT($W63:$Y63)=0,"",IFERROR(ROUND((SUM($W63:$Y63)/SUM($W$10:$Y$10))*$Z$10,2),"")) | AA63: =IF($Z63="","",ROUND($Z63*$AA$10,2)) | AB63: =IF(ISERROR(IF($Z63="","",ROUND(SUM($M63,$S63,$AA63),2))),"",IF($Z63="","",ROUND(SUM($M63,$S63,$AA63),2))) | AC63: =IF(ISERROR(IF($Z63="","",VLOOKUP(AB63,NewTransmu,4,TRUE))),"",IF($Z63="","",VLOOKUP(AB63,NewTransmu,4,TRUE))) | AD63: =IF(ISERROR(IF(AC63="","",VLOOKUP(AC63,DESCRIPTORS,4,TRUE))),"",IF(AC63="","",VLOOKUP(AC63,DESCRIPTORS,4,TRUE))) | AS63: =(T63/$T$10)*100 -> #DIV/0! | AT63: =(U63/$U$10)*100 -> #DIV/0! | AU63: =(V63/$V$10)*100 -> #DIV/0!
A64: 2 | B64: ='INPUT DATA'!P10 -> 0 | K64: =IF(COUNT($F64:$J64)=0,"",SUM($F64:$J64)) | L64: =IF(ISERROR(IF($K64="","",ROUND(($K64/$K$10)*$L$10,2))),"",IF($K64="","",ROUND(($K64/$K$10)*$L$10,2))) | M64: =IF($L64="","",ROUND($L64*$M$10,2)) | Q64: =IF(COUNT($N64:$P64)=0,"",SUM($N64:$P64)) | R64: =IF(ISERROR(IF($Q64="","",ROUND(($Q64/$Q$10)*$R$10,2))),"",IF($Q64="","",ROUND(($Q64/$Q$10)*$R$10,2))) | S64: =IF($R64="","",ROUND($R64*$S$10,2)) | W64: =IF(OR(T64="",$T$10=""),"",(T64/$T$10)*$W$10) | X64: =IF(OR(U64="",$U$10=""),"",(U64/$U$10)*$X$10) | Y64: =IF(OR(V64="",$V$10=""),"",(V64/$V$10)*$Y$10) | Z64: =IF(COUNT($W64:$Y64)=0,"",IFERROR(ROUND((SUM($W64:$Y64)/SUM($W$10:$Y$10))*$Z$10,2),"")) | AA64: =IF($Z64="","",ROUND($Z64*$AA$10,2)) | AB64: =IF(ISERROR(IF($Z64="","",ROUND(SUM($M64,$S64,$AA64),2))),"",IF($Z64="","",ROUND(SUM($M64,$S64,$AA64),2))) | AC64: =IF(ISERROR(IF($Z64="","",VLOOKUP(AB64,NewTransmu,4,TRUE))),"",IF($Z64="","",VLOOKUP(AB64,NewTransmu,4,TRUE))) | AD64: =IF(ISERROR(IF(AC64="","",VLOOKUP(AC64,DESCRIPTORS,4,TRUE))),"",IF(AC64="","",VLOOKUP(AC64,DESCRIPTORS,4,TRUE))) | AS64: =(T64/$T$10)*100 -> #DIV/0! | AT64: =(U64/$U$10)*100 -> #DIV/0! | AU64: =(V64/$V$10)*100 -> #DIV/0!
A65: 3 | B65: ='INPUT DATA'!P11 -> 0 | K65: =IF(COUNT($F65:$J65)=0,"",SUM($F65:$J65)) | L65: =IF(ISERROR(IF($K65="","",ROUND(($K65/$K$10)*$L$10,2))),"",IF($K65="","",ROUND(($K65/$K$10)*$L$10,2))) | M65: =IF($L65="","",ROUND($L65*$M$10,2)) | Q65: =IF(COUNT($N65:$P65)=0,"",SUM($N65:$P65)) | R65: =IF(ISERROR(IF($Q65="","",ROUND(($Q65/$Q$10)*$R$10,2))),"",IF($Q65="","",ROUND(($Q65/$Q$10)*$R$10,2))) | S65: =IF($R65="","",ROUND($R65*$S$10,2)) | W65: =IF(OR(T65="",$T$10=""),"",(T65/$T$10)*$W$10) | X65: =IF(OR(U65="",$U$10=""),"",(U65/$U$10)*$X$10) | Y65: =IF(OR(V65="",$V$10=""),"",(V65/$V$10)*$Y$10) | Z65: =IF(COUNT($W65:$Y65)=0,"",IFERROR(ROUND((SUM($W65:$Y65)/SUM($W$10:$Y$10))*$Z$10,2),"")) | AA65: =IF($Z65="","",ROUND($Z65*$AA$10,2)) | AB65: =IF(ISERROR(IF($Z65="","",ROUND(SUM($M65,$S65,$AA65),2))),"",IF($Z65="","",ROUND(SUM($M65,$S65,$AA65),2))) | AC65: =IF(ISERROR(IF($Z65="","",VLOOKUP(AB65,NewTransmu,4,TRUE))),"",IF($Z65="","",VLOOKUP(AB65,NewTransmu,4,TRUE))) | AD65: =IF(ISERROR(IF(AC65="","",VLOOKUP(AC65,DESCRIPTORS,4,TRUE))),"",IF(AC65="","",VLOOKUP(AC65,DESCRIPTORS,4,TRUE))) | AS65: =(T65/$T$10)*100 -> #DIV/0! | AT65: =(U65/$U$10)*100 -> #DIV/0! | AU65: =(V65/$V$10)*100 -> #DIV/0!
A66: 4 | B66: ='INPUT DATA'!P12 -> 0 | K66: =IF(COUNT($F66:$J66)=0,"",SUM($F66:$J66)) | L66: =IF(ISERROR(IF($K66="","",ROUND(($K66/$K$10)*$L$10,2))),"",IF($K66="","",ROUND(($K66/$K$10)*$L$10,2))) | M66: =IF($L66="","",ROUND($L66*$M$10,2)) | Q66: =IF(COUNT($N66:$P66)=0,"",SUM($N66:$P66)) | R66: =IF(ISERROR(IF($Q66="","",ROUND(($Q66/$Q$10)*$R$10,2))),"",IF($Q66="","",ROUND(($Q66/$Q$10)*$R$10,2))) | S66: =IF($R66="","",ROUND($R66*$S$10,2)) | W66: =IF(OR(T66="",$T$10=""),"",(T66/$T$10)*$W$10) | X66: =IF(OR(U66="",$U$10=""),"",(U66/$U$10)*$X$10) | Y66: =IF(OR(V66="",$V$10=""),"",(V66/$V$10)*$Y$10) | Z66: =IF(COUNT($W66:$Y66)=0,"",IFERROR(ROUND((SUM($W66:$Y66)/SUM($W$10:$Y$10))*$Z$10,2),"")) | AA66: =IF($Z66="","",ROUND($Z66*$AA$10,2)) | AB66: =IF(ISERROR(IF($Z66="","",ROUND(SUM($M66,$S66,$AA66),2))),"",IF($Z66="","",ROUND(SUM($M66,$S66,$AA66),2))) | AC66: =IF(ISERROR(IF($Z66="","",VLOOKUP(AB66,NewTransmu,4,TRUE))),"",IF($Z66="","",VLOOKUP(AB66,NewTransmu,4,TRUE))) | AD66: =IF(ISERROR(IF(AC66="","",VLOOKUP(AC66,DESCRIPTORS,4,TRUE))),"",IF(AC66="","",VLOOKUP(AC66,DESCRIPTORS,4,TRUE))) | AS66: =(T66/$T$10)*100 -> #DIV/0! | AT66: =(U66/$U$10)*100 -> #DIV/0! | AU66: =(V66/$V$10)*100 -> #DIV/0!
A67: 5 | B67: ='INPUT DATA'!P13 -> 0 | K67: =IF(COUNT($F67:$J67)=0,"",SUM($F67:$J67)) | L67: =IF(ISERROR(IF($K67="","",ROUND(($K67/$K$10)*$L$10,2))),"",IF($K67="","",ROUND(($K67/$K$10)*$L$10,2))) | M67: =IF($L67="","",ROUND($L67*$M$10,2)) | Q67: =IF(COUNT($N67:$P67)=0,"",SUM($N67:$P67)) | R67: =IF(ISERROR(IF($Q67="","",ROUND(($Q67/$Q$10)*$R$10,2))),"",IF($Q67="","",ROUND(($Q67/$Q$10)*$R$10,2))) | S67: =IF($R67="","",ROUND($R67*$S$10,2)) | W67: =IF(OR(T67="",$T$10=""),"",(T67/$T$10)*$W$10) | X67: =IF(OR(U67="",$U$10=""),"",(U67/$U$10)*$X$10) | Y67: =IF(OR(V67="",$V$10=""),"",(V67/$V$10)*$Y$10) | Z67: =IF(COUNT($W67:$Y67)=0,"",IFERROR(ROUND((SUM($W67:$Y67)/SUM($W$10:$Y$10))*$Z$10,2),"")) | AA67: =IF($Z67="","",ROUND($Z67*$AA$10,2)) | AB67: =IF(ISERROR(IF($Z67="","",ROUND(SUM($M67,$S67,$AA67),2))),"",IF($Z67="","",ROUND(SUM($M67,$S67,$AA67),2))) | AC67: =IF(ISERROR(IF($Z67="","",VLOOKUP(AB67,NewTransmu,4,TRUE))),"",IF($Z67="","",VLOOKUP(AB67,NewTransmu,4,TRUE))) | AD67: =IF(ISERROR(IF(AC67="","",VLOOKUP(AC67,DESCRIPTORS,4,TRUE))),"",IF(AC67="","",VLOOKUP(AC67,DESCRIPTORS,4,TRUE))) | AS67: =(T67/$T$10)*100 -> #DIV/0! | AT67: =(U67/$U$10)*100 -> #DIV/0! | AU67: =(V67/$V$10)*100 -> #DIV/0!
A68: 6 | B68: ='INPUT DATA'!P14 -> 0 | K68: =IF(COUNT($F68:$J68)=0,"",SUM($F68:$J68)) | L68: =IF(ISERROR(IF($K68="","",ROUND(($K68/$K$10)*$L$10,2))),"",IF($K68="","",ROUND(($K68/$K$10)*$L$10,2))) | M68: =IF($L68="","",ROUND($L68*$M$10,2)) | Q68: =IF(COUNT($N68:$P68)=0,"",SUM($N68:$P68)) | R68: =IF(ISERROR(IF($Q68="","",ROUND(($Q68/$Q$10)*$R$10,2))),"",IF($Q68="","",ROUND(($Q68/$Q$10)*$R$10,2))) | S68: =IF($R68="","",ROUND($R68*$S$10,2)) | W68: =IF(OR(T68="",$T$10=""),"",(T68/$T$10)*$W$10) | X68: =IF(OR(U68="",$U$10=""),"",(U68/$U$10)*$X$10) | Y68: =IF(OR(V68="",$V$10=""),"",(V68/$V$10)*$Y$10) | Z68: =IF(COUNT($W68:$Y68)=0,"",IFERROR(ROUND((SUM($W68:$Y68)/SUM($W$10:$Y$10))*$Z$10,2),"")) | AA68: =IF($Z68="","",ROUND($Z68*$AA$10,2)) | AB68: =IF(ISERROR(IF($Z68="","",ROUND(SUM($M68,$S68,$AA68),2))),"",IF($Z68="","",ROUND(SUM($M68,$S68,$AA68),2))) | AC68: =IF(ISERROR(IF($Z68="","",VLOOKUP(AB68,NewTransmu,4,TRUE))),"",IF($Z68="","",VLOOKUP(AB68,NewTransmu,4,TRUE))) | AD68: =IF(ISERROR(IF(AC68="","",VLOOKUP(AC68,DESCRIPTORS,4,TRUE))),"",IF(AC68="","",VLOOKUP(AC68,DESCRIPTORS,4,TRUE))) | AS68: =(T68/$T$10)*100 -> #DIV/0! | AT68: =(U68/$U$10)*100 -> #DIV/0! | AU68: =(V68/$V$10)*100 -> #DIV/0!
