Workbook

Sheet Home

Sheet INPUT DATA
A1: Input Data Sheet for Electronic-Class Record (ECR) for Class Adviser
B7: SCHOOL INFORMATION | J7: LEARNERS' DATA
C10: REGION | E10: : | K10: MALE | M10: LRN | N10: BIRTHDATE | P10: FEMALE | R10: LRN | S10: BIRTHDATE
C11: DIVISION | E11: : | K11: 1 | P11: 1
C12: CITY/MUNICIPALITY | E12: : | K12: 2 | P12: 2
C13: DISTRICT | E13: : | K13: 3 | P13: 3
K14: 4 | P14: 4
C15: SCHOOL ID | E15: : | K15: 5 | P15: 5
C16: SCHOOL NAME | E16: : | K16: 6 | P16: 6
K17: 7 | P17: 7
C18: SCHOOL YEAR | E18: : | K18: 8 | P18: 8
C19: SCHOOL HEAD | E19: : | K19: 9 | P19: 9
K20: 10 | P20: 10
K21: 11 | P21: 11
K22: 12 | P22: 12
B23: TEACHER, GRADE LEVEL, SECTION INFORMATION | K23: 13 | P23: 13
K24: 14 | P24: 14
K25: 15 | P25: 15
C26: ADVISER | E26: : | K26: 16 | P26: 16
C27: GRADE LEVEL | E27: : | G27: (Accepts Grade 11 only) | K27: 17 | P27: 17
C28: TRACK | E28: : | K28: 18 | P28: 18
C29: SECTION | E29: : | K29: 19 | P29: 19
K30: 20 | P30: 20
C31: IMPORTANT NOTE: This is the official and final version of the file. All tabs are password-protected to prevent accidental formula edits and maintain the accuracy and integrity of the data. If you identify any inconsistencies or issues, particularly with the formulas, please report them for appropriate review and necessary correction. | K31: 21 | P31: 21
K32: 22 | P32: 22
K33: 23 | P33: 23
K34: 24 | P34: 24
K35: 25 | P35: 25
K36: 26 | P36: 26
K37: 27 | P37: 27
B38: Sheet Protection Password: password123 | K38: 28 | P38: 28
K39: 29 | P39: 29
K40: 30 | P40: 30
K41: 31 | P41: 31
K42: 32 | P42: 32
K43: 33 | P43: 33
K44: 34 | P44: 34
K45: 35 | P45: 35
K46: 36 | P46: 36
K47: 37 | P47: 37
...

Sheet TERM 1 SUMMARY
A1: CLASS SUMMARY
D5: REGION | E5: =IF('INPUT DATA'!F10="","",'INPUT DATA'!F10) | I5: DIVISION | J5: =IF('INPUT DATA'!F11="","",'INPUT DATA'!F11)
D6: SCHOOL NAME | E6: =IF('INPUT DATA'!F16="","",'INPUT DATA'!F16) | I6: SCHOOL ID | J6: =IF('INPUT DATA'!F15="","",'INPUT DATA'!F15) | M6: SCHOOL YEAR | O6: =IF('INPUT DATA'!F18="","",'INPUT DATA'!F18)
B9: FIRST TERM | F9: GRADE LEVEL | G9: =IF('INPUT DATA'!F27="","",'INPUT DATA'!F27) | L9: SECTION | O9: =IF('INPUT DATA'!F29="","",'INPUT DATA'!F29)
F10: TRACK | G10: =IF('INPUT DATA'!F28="","",'INPUT DATA'!F28) | L10: ADVISER | O10: =IF('INPUT DATA'!F26="","",'INPUT DATA'!F26)
B11: LEARNERS' NAMES | F11: LRN | H11: Date of Birth | I11: Age | J11: Sex | K11: Learning Areas
K12: Core Subjects | R12: Elective Subjects
K13: Effective Communication and Mabisang Komunikasyon | N13: General Mathematics | O13: General Science | P13: Life and Career Skills | Q13: PKLP | R13: Academic Elective 1
K14: Term Grade | L14: Effective Communication | M14: Mabisang Komunikasyon
B15: MALE
B16: 1 | C16: =IF('INPUT DATA'!L11="","",'INPUT DATA'!L11) | F16: =IF('INPUT DATA'!M11="","",'INPUT DATA'!M11) | H16: =IF('INPUT DATA'!N11="","",'INPUT DATA'!N11) | I16: =IF(H16="","",DATEDIF(H16,TODAY(),"Y")) | J16: M
B17: 2 | C17: =IF('INPUT DATA'!L12="","",'INPUT DATA'!L12) | F17: =IF('INPUT DATA'!M12="","",'INPUT DATA'!M12) | H17: =IF('INPUT DATA'!N12="","",'INPUT DATA'!N12) | I17: =IF(H17="","",DATEDIF(H17,TODAY(),"Y")) | J17: M
B18: 3 | C18: =IF('INPUT DATA'!L13="","",'INPUT DATA'!L13) | F18: =IF('INPUT DATA'!M13="","",'INPUT DATA'!M13) | H18: =IF('INPUT DATA'!N13="","",'INPUT DATA'!N13) | I18: =IF(H18="","",DATEDIF(H18,TODAY(),"Y")) | J18: M
B19: 4 | C19: =IF('INPUT DATA'!L14="","",'INPUT DATA'!L14) | F19: =IF('INPUT DATA'!M14="","",'INPUT DATA'!M14) | H19: =IF('INPUT DATA'!N14="","",'INPUT DATA'!N14) | I19: =IF(H19="","",DATEDIF(H19,TODAY(),"Y")) | J19: M
B20: 5 | C20: =IF('INPUT DATA'!L15="","",'INPUT DATA'!L15) | F20: =IF('INPUT DATA'!M15="","",'INPUT DATA'!M15) | H20: =IF('INPUT DATA'!N15="","",'INPUT DATA'!N15) | I20: =IF(H20="","",DATEDIF(H20,TODAY(),"Y")) | J20: M
B21: 6 | C21: =IF('INPUT DATA'!L16="","",'INPUT DATA'!L16) | F21: =IF('INPUT DATA'!M16="","",'INPUT DATA'!M16) | H21: =IF('INPUT DATA'!N16="","",'INPUT DATA'!N16) | I21: =IF(H21="","",DATEDIF(H21,TODAY(),"Y"))
B22: 7 | C22: =IF('INPUT DATA'!L17="","",'INPUT DATA'!L17) | F22: =IF('INPUT DATA'!M17="","",'INPUT DATA'!M17) | H22: =IF('INPUT DATA'!N17="","",'INPUT DATA'!N17) | I22: =IF(H22="","",DATEDIF(H22,TODAY(),"Y"))
B23: 8 | C23: =IF('INPUT DATA'!L18="","",'INPUT DATA'!L18) | F23: =IF('INPUT DATA'!M18="","",'INPUT DATA'!M18) | H23: =IF('INPUT DATA'!N18="","",'INPUT DATA'!N18) | I23: =IF(H23="","",DATEDIF(H23,TODAY(),"Y"))
B24: 9 | C24: =IF('INPUT DATA'!L19="","",'INPUT DATA'!L19) | F24: =IF('INPUT DATA'!M19="","",'INPUT DATA'!M19) | H24: =IF('INPUT DATA'!N19="","",'INPUT DATA'!N19) | I24: =IF(H24="","",DATEDIF(H24,TODAY(),"Y"))
B25: 10 | C25: =IF('INPUT DATA'!L20="","",'INPUT DATA'!L20) | F25: =IF('INPUT DATA'!M20="","",'INPUT DATA'!M20) | H25: =IF('INPUT DATA'!N20="","",'INPUT DATA'!N20) | I25: =IF(H25="","",DATEDIF(H25,TODAY(),"Y"))
B26: 11 | C26: =IF('INPUT DATA'!L21="","",'INPUT DATA'!L21) | F26: =IF('INPUT DATA'!M21="","",'INPUT DATA'!M21) | H26: =IF('INPUT DATA'!N21="","",'INPUT DATA'!N21) | I26: =IF(H26="","",DATEDIF(H26,TODAY(),"Y"))
B27: 12 | C27: =IF('INPUT DATA'!L22="","",'INPUT DATA'!L22) | F27: =IF('INPUT DATA'!M22="","",'INPUT DATA'!M22) | H27: =IF('INPUT DATA'!N22="","",'INPUT DATA'!N22) | I27: =IF(H27="","",DATEDIF(H27,TODAY(),"Y"))
B28: 13 | C28: =IF('INPUT DATA'!L23="","",'INPUT DATA'!L23) | F28: =IF('INPUT DATA'!M23="","",'INPUT DATA'!M23) | H28: =IF('INPUT DATA'!N23="","",'INPUT DATA'!N23) | I28: =IF(H28="","",DATEDIF(H28,TODAY(),"Y"))
B29: 14 | C29: =IF('INPUT DATA'!L24="","",'INPUT DATA'!L24) | F29: =IF('INPUT DATA'!M24="","",'INPUT DATA'!M24) | H29: =IF('INPUT DATA'!N24="","",'INPUT DATA'!N24) | I29: =IF(H29="","",DATEDIF(H29,TODAY(),"Y"))
B30: 15 | C30: =IF('INPUT DATA'!L25="","",'INPUT DATA'!L25) | F30: =IF('INPUT DATA'!M25="","",'INPUT DATA'!M25) | H30: =IF('INPUT DATA'!N25="","",'INPUT DATA'!N25) | I30: =IF(H30="","",DATEDIF(H30,TODAY(),"Y"))
B31: 16 | C31: =IF('INPUT DATA'!L26="","",'INPUT DATA'!L26) | F31: =IF('INPUT DATA'!M26="","",'INPUT DATA'!M26) | H31: =IF('INPUT DATA'!N26="","",'INPUT DATA'!N26) | I31: =IF(H31="","",DATEDIF(H31,TODAY(),"Y"))
B32: 17 | C32: =IF('INPUT DATA'!L27="","",'INPUT DATA'!L27) | F32: =IF('INPUT DATA'!M27="","",'INPUT DATA'!M27) | H32: =IF('INPUT DATA'!N27="","",'INPUT DATA'!N27) | I32: =IF(H32="","",DATEDIF(H32,TODAY(),"Y"))
... B60: 45 | C60: =IF('INPUT DATA'!L55="","",'INPUT DATA'!L55) | F60: =IF('INPUT DATA'!M55="","",'INPUT DATA'!M55) | H60: =IF('INPUT DATA'!N55="","",'INPUT DATA'!N55) | I60: =IF(H60="","",DATEDIF(H60,TODAY(),"Y"))
B61: 46 | C61: =IF('INPUT DATA'!L56="","",'INPUT DATA'!L56) | F61: =IF('INPUT DATA'!M56="","",'INPUT DATA'!M56) | H61: =IF('INPUT DATA'!N56="","",'INPUT DATA'!N56) | I61: =IF(H61="","",DATEDIF(H61,TODAY(),"Y")) | J61: M
B62: 47 | C62: =IF('INPUT DATA'!L57="","",'INPUT DATA'!L57) | F62: =IF('INPUT DATA'!M57="","",'INPUT DATA'!M57) | H62: =IF('INPUT DATA'!N57="","",'INPUT DATA'!N57) | I62: =IF(H62="","",DATEDIF(H62,TODAY(),"Y"))
B63: 48 | C63: =IF('INPUT DATA'!L58="","",'INPUT DATA'!L58) | F63: =IF('INPUT DATA'!M58="","",'INPUT DATA'!M58) | H63: =IF('INPUT DATA'!N58="","",'INPUT DATA'!N58) | I63: =IF(H63="","",DATEDIF(H63,TODAY(),"Y"))
B64: 49 | C64: =IF('INPUT DATA'!L59="","",'INPUT DATA'!L59) | F64: =IF('INPUT DATA'!M59="","",'INPUT DATA'!M59) | H64: =IF('INPUT DATA'!N59="","",'INPUT DATA'!N59) | I64: =IF(H64="","",DATEDIF(H64,TODAY(),"Y"))
B65: 50 | C65: =IF('INPUT DATA'!L60="","",'INPUT DATA'!L60) | F65: =IF('INPUT DATA'!M60="","",'INPUT DATA'!M60) | H65: =IF('INPUT DATA'!N60="","",'INPUT DATA'!N60) | I65: =IF(H65="","",DATEDIF(H65,TODAY(),"Y"))
B66: FEMALE
B67: 1 | C67: =IF('INPUT DATA'!Q11="","",'INPUT DATA'!Q11) | F67: =IF('INPUT DATA'!T11="","",'INPUT DATA'!T11) | H67: =IF('INPUT DATA'!S11="","",'INPUT DATA'!S11) | I67: =IF(H67="","",DATEDIF(H67,TODAY(),"Y")) | J67: F
B68: 2 | C68: =IF('INPUT DATA'!Q12="","",'INPUT DATA'!Q12) | F68: =IF('INPUT DATA'!T12="","",'INPUT DATA'!T12) | H68: =IF('INPUT DATA'!S12="","",'INPUT DATA'!S12) | I68: =IF(H68="","",DATEDIF(H68,TODAY(),"Y")) | J68: F
B69: 3 | C69: =IF('INPUT DATA'!Q13="","",'INPUT DATA'!Q13) | F69: =IF('INPUT DATA'!T13="","",'INPUT DATA'!T13) | H69: =IF('INPUT DATA'!S13="","",'INPUT DATA'!S13) | I69: =IF(H69="","",DATEDIF(H69,TODAY(),"Y")) | J69: F
B70: 4 | C70: =IF('INPUT DATA'!Q14="","",'INPUT DATA'!Q14) | F70: =IF('INPUT DATA'!T14="","",'INPUT DATA'!T14) | H70: =IF('INPUT DATA'!S14="","",'INPUT DATA'!S14) | I70: =IF(H70="","",DATEDIF(H70,TODAY(),"Y"))
B71: 5 | C71: =IF('INPUT DATA'!Q15="","",'INPUT DATA'!Q15) | F71: =IF('INPUT DATA'!T15="","",'INPUT DATA'!T15) | H71: =IF('INPUT DATA'!S15="","",'INPUT DATA'!S15) | I71: =IF(H71="","",DATEDIF(H71,TODAY(),"Y"))
B72: 6 | C72: =IF('INPUT DATA'!Q16="","",'INPUT DATA'!Q16) | F72: =IF('INPUT DATA'!T16="","",'INPUT DATA'!T16) | H72: =IF('INPUT DATA'!S16="","",'INPUT DATA'!S16) | I72: =IF(H72="","",DATEDIF(H72,TODAY(),"Y"))
...

Sheet TERM 2 SUMMARY
A1: CLASS SUMMARY
D5: REGION | E5: =IF('INPUT DATA'!F10="","",'INPUT DATA'!F10) | I5: DIVISION | J5: =IF('INPUT DATA'!F11="","",'INPUT DATA'!F11)
D6: SCHOOL NAME | E6: =IF('INPUT DATA'!F16="","",'INPUT DATA'!F16) | I6: SCHOOL ID | J6: =IF('INPUT DATA'!F15="","",'INPUT DATA'!F15) | M6: SCHOOL YEAR | O6: =IF('INPUT DATA'!F18="","",'INPUT DATA'!F18)
B9: FIRST TERM | F9: GRADE LEVEL | G9: =IF('INPUT DATA'!F27="","",'INPUT DATA'!F27) | L9: SECTION | O9: =IF('INPUT DATA'!F29="","",'INPUT DATA'!F29)
F10: TRACK | G10: =IF('INPUT DATA'!F28="","",'INPUT DATA'!F28) | L10: ADVISER | O10: =IF('INPUT DATA'!F26="","",'INPUT DATA'!F26)
B11: LEARNERS' NAMES | F11: LRN | H11: Date of Birth | I11: Age | J11: Sex | K11: Learning Areas
K12: Core Subjects | R12: Elective Subjects
K13: Effective Communication and Mabisang Komunikasyon | N13: General Mathematics | O13: General Science | P13: Life and Career Skills | Q13: PKLP | R13: Academic Elective 2
K14: Term Grade | L14: Effective Communication | M14: Mabisang Komunikasyon
B15: MALE
B16: 1 | C16: =IF('INPUT DATA'!L11="","",'INPUT DATA'!L11) | F16: =IF('INPUT DATA'!M11="","",'INPUT DATA'!M11) | H16: =IF('INPUT DATA'!N11="","",'INPUT DATA'!N11) | I16: =IF(H16="","",DATEDIF(H16,TODAY(),"")) | J16: M
B17: 2 | C17: =IF('INPUT DATA'!L12="","",'INPUT DATA'!L12) | F17: =IF('INPUT DATA'!M12="","",'INPUT DATA'!M12) | H17: =IF('INPUT DATA'!N12="","",'INPUT DATA'!N12) | I17: =IF(H17="","",DATEDIF(H17,TODAY(),"Y")) | J17: M
B18: 3 | C18: =IF('INPUT DATA'!L13="","",'INPUT DATA'!L13) | F18: =IF('INPUT DATA'!M13="","",'INPUT DATA'!M13) | H18: =IF('INPUT DATA'!N13="","",'INPUT DATA'!N13) | I18: =IF(H18="","",DATEDIF(H18,TODAY(),"Y")) | J18: M
B19: 4 | C19: =IF('INPUT DATA'!L14="","",'INPUT DATA'!L14) | F19: =IF('INPUT DATA'!M14="","",'INPUT DATA'!M14) | H19: =IF('INPUT DATA'!N14="","",'INPUT DATA'!N14) | I19: =IF(H19="","",DATEDIF(H19,TODAY(),"Y"))
B20: 5 | C20: =IF('INPUT DATA'!L15="","",'INPUT DATA'!L15) | F20: =IF('INPUT DATA'!M15="","",'INPUT DATA'!M15) | H20: =IF('INPUT DATA'!N15="","",'INPUT DATA'!N15) | I20: =IF(H20="","",DATEDIF(H20,TODAY(),"Y"))
B21: 6 | C21: =IF('INPUT DATA'!L16="","",'INPUT DATA'!L16) | F21: =IF('INPUT DATA'!M16="","",'INPUT DATA'!M16) | H21: =IF('INPUT DATA'!N16="","",'INPUT DATA'!N16) | I21: =IF(H21="","",DATEDIF(H21,TODAY(),"Y"))
B22: 7 | C22: =IF('INPUT DATA'!L17="","",'INPUT DATA'!L17) | F22: =IF('INPUT DATA'!M17="","",'INPUT DATA'!M17) | H22: =IF('INPUT DATA'!N17="","",'INPUT DATA'!N17) | I22: =IF(H22="","",DATEDIF(H22,TODAY(),"Y"))
B23: 8 | C23: =IF('INPUT DATA'!L18="","",'INPUT DATA'!L18) | F23: =IF('INPUT DATA'!M18="","",'INPUT DATA'!M18) | H23: =IF('INPUT DATA'!N18="","",'INPUT DATA'!N18) | I23: =IF(H23="","",DATEDIF(H23,TODAY(),"Y"))
B24: 9 | C24: =IF('INPUT DATA'!L19="","",'INPUT DATA'!L19) | F24: =IF('INPUT DATA'!M19="","",'INPUT DATA'!M19) | H24: =IF('INPUT DATA'!N19="","",'INPUT DATA'!N19) | I24: =IF(H24="","",DATEDIF(H24,TODAY(),"Y"))
B25: 10 | C25: =IF('INPUT DATA'!L20="","",'INPUT DATA'!L20) | F25: =IF('INPUT DATA'!M20="","",'INPUT DATA'!M20) | H25: =IF('INPUT DATA'!N20="","",'INPUT DATA'!N20) | I25: =IF(H25="","",DATEDIF(H25,TODAY(),"Y"))
B26: 11 | C26: =IF('INPUT DATA'!L21="","",'INPUT DATA'!L21) | F26: =IF('INPUT DATA'!M21="","",'INPUT DATA'!M21) | H26: =IF('INPUT DATA'!N21="","",'INPUT DATA'!N21) | I26: =IF(H26="","",DATEDIF(H26,TODAY(),"Y"))
B27: 12 | C27: =IF('INPUT DATA'!L22="","",'INPUT DATA'!L22) | F27: =IF('INPUT DATA'!M22="","",'INPUT DATA'!M22) | H27: =IF('INPUT DATA'!N22="","",'INPUT DATA'!N22) | I27: =IF(H27="","",DATEDIF(H27,TODAY(),"Y"))
B28: 13 | C28: =IF('INPUT DATA'!L23="","",'INPUT DATA'!L23) | F28: =IF('INPUT DATA'!M23="","",'INPUT DATA'!M23) | H28: =IF('INPUT DATA'!N23="","",'INPUT DATA'!N23) | I28: =IF(H28="","",DATEDIF(H28,TODAY(),"Y"))
B29: 14 | C29: =IF('INPUT DATA'!L24="","",'INPUT DATA'!L24) | F29: =IF('INPUT DATA'!M24="","",'INPUT DATA'!M24) | H29: =IF('INPUT DATA'!N24="","",'INPUT DATA'!N24) | I29: =IF(H29="","",DATEDIF(H29,TODAY(),"Y"))
B30: 15 | C30: =IF('INPUT DATA'!L25="","",'INPUT DATA'!L25) | F30: =IF('INPUT DATA'!M25="","",'INPUT DATA'!M25) | H30: =IF('INPUT DATA'!N25="","",'INPUT DATA'!N25) | I30: =IF(H30="","",DATEDIF(H30,TODAY(),"Y"))
... B65: 50 | C65: =IF('INPUT DATA'!L60="","",'INPUT DATA'!L60) | F65: =IF('INPUT DATA'!M60="","",'INPUT DATA'!M60) | H65: =IF('INPUT DATA'!N60="","",'INPUT DATA'!N60) | I65: =IF(H65="","",DATEDIF(H65,TODAY(),"Y"))
B66: FEMALE
B67: 1 | C67: =IF('INPUT DATA'!Q11="","",'INPUT DATA'!Q11) | F67: =IF('INPUT DATA'!T11="","",'INPUT DATA'!T11) | H67: =IF('INPUT DATA'!S11="","",'INPUT DATA'!S11) | I67: =IF(H67="","",DATEDIF(H67,TODAY(),"Y")) | J67: F
B68: 2 | C68: =IF('INPUT DATA'!Q12="","",'INPUT DATA'!Q12) | F68: =IF('INPUT DATA'!T12="","",'INPUT DATA'!T12) | H68: =IF('INPUT DATA'!S12="","",'INPUT DATA'!S12) | I68: =IF(H68="","",DATEDIF(H68,TODAY(),"Y")) | J68: F
B69: 3 | C69: =IF('INPUT DATA'!Q13="","",'INPUT DATA'!Q13) | F69: =IF('INPUT DATA'!T13="","",'INPUT DATA'!T13) | H69: =IF('INPUT DATA'!S13="","",'INPUT DATA'!S13) | I69: =IF(H69="","",DATEDIF(H69,TODAY(),"Y")) | J69: F
B70: 4 | C70: =IF('INPUT DATA'!Q14="","",'INPUT DATA'!Q14) | F70: =IF('INPUT DATA'!T14="","",'INPUT DATA'!T14) | H70: =IF('INPUT DATA'!S14="","",'INPUT DATA'!S14) | I70: =IF(H70="","",DATEDIF(H70,TODAY(),"Y"))
B71: 5 | C71: =IF('INPUT DATA'!Q15="","",'INPUT DATA'!Q15) | F71: =IF('INPUT DATA'!T15="","",'INPUT DATA'!T15) | H71: =IF('INPUT DATA'!S15="","",'INPUT DATA'!S15) | I71: =IF(H71="","",DATEDIF(H71,TODAY(),"Y"))
B72: 6 | C72: =IF('INPUT DATA'!Q16="","",'INPUT DATA'!Q16) | F72: =IF('INPUT DATA'!T16="","",'INPUT DATA'!T16) | H72: =IF('INPUT DATA'!S16="","",'INPUT DATA'!S16) | I72: =IF(H72="","",DATEDIF(H72,TODAY(),"Y"))
B73: 7 | C73: =IF('INPUT DATA'!Q17="","",'INPUT DATA'!Q17) | F73: =IF('INPUT DATA'!T17="","",'INPUT DATA'!T17) | H73: =IF('INPUT DATA'!S17="","",'INPUT DATA'!S17) | I73: =IF(H73="","",DATEDIF(H73,TODAY(),"Y"))
B74: 8 | C74: =IF('INPUT DATA'!Q18="","",'INPUT DATA'!Q18) | F74: =IF('INPUT DATA'!T18="","",'INPUT DATA'!T18) | H74: =IF('INPUT DATA'!S18="","",'INPUT DATA'!S18) | I74: =IF(H74="","",DATEDIF(H74,TODAY(),"Y"))
B75: 9 | C75: =IF('INPUT DATA'!Q19="","",'INPUT DATA'!Q19) | F75: =IF('INPUT DATA'!T19="","",'INPUT DATA'!T19) | H75: =IF('INPUT DATA'!S19="","",'INPUT DATA'!S19) | I75: =IF(H75="","",DATEDIF(H75,TODAY(),"Y"))
B76: 10 | C76: =IF('INPUT DATA'!Q20="","",'INPUT DATA'!Q20) | F76: =IF('INPUT DATA'!T20="","",'INPUT DATA'!T20) | H76: =IF('INPUT DATA'!S20="","",'INPUT DATA'!S20) | I76: =IF(H76="","",DATEDIF(H76,TODAY(),"Y"))
B77: 11 | C77: =IF('INPUT DATA'!Q21="","",'INPUT DATA'!Q21) | F77: =IF('INPUT DATA'!T21="","",'INPUT DATA'!T21) | H77: =IF('INPUT DATA'!S21="","",'INPUT DATA'!S21) | I77: =IF(H77="","",DATEDIF(H77,TODAY(),"Y"))
B78: 12 | C78: =IF('INPUT DATA'!Q22="","",'INPUT DATA'!Q22) | F78: =IF('INPUT DATA'!T22="","",'INPUT DATA'!T22) | H78: =IF('INPUT DATA'!S22="","",'INPUT DATA'!S22) | I78: =IF(H78="","",DATEDIF(H78,TODAY(),"Y"))
B79: 13 | C79: =IF('INPUT DATA'!Q23="","",'INPUT DATA'!Q23) | F79: =IF('INPUT DATA'!T23="","",'INPUT DATA'!T23) | H79: =IF('INPUT DATA'!S23="","",'INPUT DATA'!S23) | I79: =IF(H79="","",DATEDIF(H79,TODAY(),"Y"))
...

Sheet TERM 3 SUMMARY
A1: CLASS SUMMARY
D5: REGION | E5: =IF('INPUT DATA'!F10="","",'INPUT DATA'!F10) | I5: DIVISION | J5: =IF('INPUT DATA'!F11="","",'INPUT DATA'!F11)
D6: SCHOOL NAME | E6: =IF('INPUT DATA'!F16="","",'INPUT DATA'!F16) | I6: SCHOOL ID | J6: =IF('INPUT DATA'!F15="","",'INPUT DATA'!F15) | M6: SCHOOL YEAR | O6: =IF('INPUT DATA'!F18="","",'INPUT DATA'!F18) | R6: =IF('INPUT DATA'!F18="","",'INPUT DATA'!F18)
B9: FIRST TERM | F9: GRADE LEVEL | G9: =IF('INPUT DATA'!F27="","",'INPUT DATA'!F27) | L9: SECTION | O9: =IF('INPUT DATA'!F29="","",'INPUT DATA'!F29)
F10: TRACK | G10: =IF('INPUT DATA'!F28="","",'INPUT DATA'!F28) | L10: ADVISER | O10: =IF('INPUT DATA'!F26="","",'INPUT DATA'!F26)
B11: LEARNERS' NAMES | F11: LRN | H11: Date of Birth | I11: Age | J11: Sex | K11: Learning Areas
K12: Core Subjects | R12: Elective Subjects
K13: Effective Communication and Mabisang Komunikasyon | N13: General Mathematics | O13: General Science | P13: Life and Career Skills | Q13: PKLP | R13: Academic Elective 3
K14: Term Grade | L14: Effective Communication | M14: Mabisang Komunikasyon
B15: MALE
B16: 1 | C16: =IF('INPUT DATA'!L11="","",'INPUT DATA'!L11) | F16: =IF('INPUT DATA'!M11="","",'INPUT DATA'!M11) | H16: =IF('INPUT DATA'!N11="","",'INPUT DATA'!N11) | I16: =IF(H16="","",DATEDIF(H16,TODAY(),"Y")) | J16: M
B17: 2 | C17: =IF('INPUT DATA'!L12="","",'INPUT DATA'!L12) | F17: =IF('INPUT DATA'!M12="","",'INPUT DATA'!M12) | H17: =IF('INPUT DATA'!N12="","",'INPUT DATA'!N12) | I17: =IF(H17="","",DATEDIF(H17,TODAY(),"Y")) | J17: M
B18: 3 | C18: =IF('INPUT DATA'!L13="","",'INPUT DATA'!L13) | F18: =IF('INPUT DATA'!M13="","",'INPUT DATA'!M13) | H18: =IF('INPUT DATA'!N13="","",'INPUT DATA'!N13) | I18: =IF(H18="","",DATEDIF(H18,TODAY(),"Y")) | J18: M
B19: 4 | C19: =IF('INPUT DATA'!L14="","",'INPUT DATA'!L14) | F19: =IF('INPUT DATA'!M14="","",'INPUT DATA'!M14) | H19: =IF('INPUT DATA'!N14="","",'INPUT DATA'!N14) | I19: =IF(H19="","",DATEDIF(H19,TODAY(),"Y"))
B20: 5 | C20: =IF('INPUT DATA'!L15="","",'INPUT DATA'!L15) | F20: =IF('INPUT DATA'!M15="","",'INPUT DATA'!M15) | H20: =IF('INPUT DATA'!N15="","",'INPUT DATA'!N15) | I20: =IF(H20="","",DATEDIF(H20,TODAY(),"Y"))
B21: 6 | C21: =IF('INPUT DATA'!L16="","",'INPUT DATA'!L16) | F21: =IF('INPUT DATA'!M16="","",'INPUT DATA'!M16) | H21: =IF('INPUT DATA'!N16="","",'INPUT DATA'!N16) | I21: =IF(H21="","",DATEDIF(H21,TODAY(),"Y"))
B22: 7 | C22: =IF('INPUT DATA'!L17="","",'INPUT DATA'!L17) | F22: =IF('INPUT DATA'!M17="","",'INPUT DATA'!M17) | H22: =IF('INPUT DATA'!N17="","",'INPUT DATA'!N17) | I22: =IF(H22="","",DATEDIF(H22,TODAY(),"Y"))
B23: 8 | C23: =IF('INPUT DATA'!L18="","",'INPUT DATA'!L18) | F23: =IF('INPUT DATA'!M18="","",'INPUT DATA'!M18) | H23: =IF('INPUT DATA'!N18="","",'INPUT DATA'!N18) | I23: =IF(H23="","",DATEDIF(H23,TODAY(),"Y"))
B24: 9 | C24: =IF('INPUT DATA'!L19="","",'INPUT DATA'!L19) | F24: =IF('INPUT DATA'!M19="","",'INPUT DATA'!M19) | H24: =IF('INPUT DATA'!N19="","",'INPUT DATA'!N19) | I24: =IF(H24="","",DATEDIF(H24,TODAY(),"Y"))
B25: 10 | C25: =IF('INPUT DATA'!L20="","",'INPUT DATA'!L20) | F25: =IF('INPUT DATA'!M20="","",'INPUT DATA'!M20) | H25: =IF('INPUT DATA'!N20="","",'INPUT DATA'!N20) | I25: =IF(H25="","",DATEDIF(H25,TODAY(),"Y"))
B26: 11 | C26: =IF('INPUT DATA'!L21="","",'INPUT DATA'!L21) | F26: =IF('INPUT DATA'!M21="","",'INPUT DATA'!M21) | H26: =IF('INPUT DATA'!N21="","",'INPUT DATA'!N21) | I26: =IF(H26="","",DATEDIF(H26,TODAY(),"Y"))
B27: 12 | C27: =IF('INPUT DATA'!L22="","",'INPUT DATA'!L22) | F27: =IF('INPUT DATA'!M22="","",'INPUT DATA'!M22) | H27: =IF('INPUT DATA'!N22="","",'INPUT DATA'!N22) | I27: =IF(H27="","",DATEDIF(H27,TODAY(),"Y"))
B28: 13 | C28: =IF('INPUT DATA'!L23="","",'INPUT DATA'!L23) | F28: =IF('INPUT DATA'!M23="","",'INPUT DATA'!M23) | H28: =IF('INPUT DATA'!N23="","",'INPUT DATA'!N23) | I28: =IF(H28="","",DATEDIF(H28,TODAY(),"Y"))
B29: 14 | C29: =IF('INPUT DATA'!L24="","",'INPUT DATA'!L24) | F29: =IF('INPUT DATA'!M24="","",'INPUT DATA'!M24) | H29: =IF('INPUT DATA'!N24="","",'INPUT DATA'!N24) | I29: =IF(H29="","",DATEDIF(H29,TODAY(),"Y"))
B30: 15 | C30: =IF('INPUT DATA'!L25="","",'INPUT DATA'!L25) | F30: =IF('INPUT DATA'!M25="","",'INPUT DATA'!M25) | H30: =IF('INPUT DATA'!N25="","",'INPUT DATA'!N25) | I30: =IF(H30="","",DATEDIF(H30,TODAY(),"Y"))
... B65: 50 | C65: =IF('INPUT DATA'!L60="","",'INPUT DATA'!L60) | F65: =IF('INPUT DATA'!M60="","",'INPUT DATA'!M60) | H65: =IF('INPUT DATA'!N60="","",'INPUT DATA'!N60) | I65: =IF(H65="","",DATEDIF(H65,TODAY(),"Y"))
B66: FEMALE
B67: 1 | C67: =IF('INPUT DATA'!Q11="","",'INPUT DATA'!Q11) | F67: =IF('INPUT DATA'!T11="","",'INPUT DATA'!T11) | H67: =IF('INPUT DATA'!S11="","",'INPUT DATA'!S11) | I67: =IF(H67="","",DATEDIF(H67,TODAY(),"Y")) | J67: F
B68: 2 | C68: =IF('INPUT DATA'!Q12="","",'INPUT DATA'!Q12) | F68: =IF('INPUT DATA'!T12="","",'INPUT DATA'!T12) | H68: =IF('INPUT DATA'!S12="","",'INPUT DATA'!S12) | I68: =IF(H68="","",DATEDIF(H68,TODAY(),"Y")) | J68: F
B69: 3 | C69: =IF('INPUT DATA'!Q13="","",'INPUT DATA'!Q13) | F69: =IF('INPUT DATA'!T13="","",'INPUT DATA'!T13) | H69: =IF('INPUT DATA'!S13="","",'INPUT DATA'!S13) | I69: =IF(H69="","",DATEDIF(H69,TODAY(),"Y")) | J69: F
B70: 4 | C70: =IF('INPUT DATA'!Q14="","",'INPUT DATA'!Q14) | F70: =IF('INPUT DATA'!T14="","",'INPUT DATA'!T14) | H70: =IF('INPUT DATA'!S14="","",'INPUT DATA'!S14) | I70: =IF(H70="","",DATEDIF(H70,TODAY(),"Y"))
B71: 5 | C71: =IF('INPUT DATA'!Q15="","",'INPUT DATA'!Q15) | F71: =IF('INPUT DATA'!T15="","",'INPUT DATA'!T15) | H71: =IF('INPUT DATA'!S15="","",'INPUT DATA'!S15) | I71: =IF(H71="","",DATEDIF(H71,TODAY(),"Y"))
B72: 6 | C72: =IF('INPUT DATA'!Q16="","",'INPUT DATA'!Q16) | F72: =IF('INPUT DATA'!T16="","",'INPUT DATA'!T16) | H72: =IF('INPUT DATA'!S16="","",'INPUT DATA'!S16) | I72: =IF(H72="","",DATEDIF(H72,TODAY(),"Y"))
B73: 7 | C73: =IF('INPUT DATA'!Q17="","",'INPUT DATA'!Q17) | F73: =IF('INPUT DATA'!T17="","",'INPUT DATA'!T17) | H73: =IF('INPUT DATA'!S17="","",'INPUT DATA'!S17) | I73: =IF(H73="","",DATEDIF(H73,TODAY(),"Y"))
B74: 8 | C74: =IF('INPUT DATA'!Q18="","",'INPUT DATA'!Q18) | F74: =IF('INPUT DATA'!T18="","",'INPUT DATA'!T18) | H74: =IF('INPUT DATA'!S18="","",'INPUT DATA'!S18) | I74: =IF(H74="","",DATEDIF(H74,TODAY(),"Y"))
B75: 9 | C75: =IF('INPUT DATA'!Q19="","",'INPUT DATA'!Q19) | F75: =IF('INPUT DATA'!T19="","",'INPUT DATA'!T19) | H75: =IF('INPUT DATA'!S19="","",'INPUT DATA'!S19) | I75: =IF(H75="","",DATEDIF(H75,TODAY(),"Y"))
B76: 10 | C76: =IF('INPUT DATA'!Q20="","",'INPUT DATA'!Q20) | F76: =IF('INPUT DATA'!T20="","",'INPUT DATA'!T20) | H76: =IF('INPUT DATA'!S20="","",'INPUT DATA'!S20) | I76: =IF(H76="","",DATEDIF(H76,TODAY(),"Y"))
B77: 11 | C77: =IF('INPUT DATA'!Q21="","",'INPUT DATA'!Q21) | F77: =IF('INPUT DATA'!T21="","",'INPUT DATA'!T21) | H77: =IF('INPUT DATA'!S21="","",'INPUT DATA'!S21) | I77: =IF(H77="","",DATEDIF(H77,TODAY(),"Y"))
B78: 12 | C78: =IF('INPUT DATA'!Q22="","",'INPUT DATA'!Q22) | F78: =IF('INPUT DATA'!T22="","",'INPUT DATA'!T22) | H78: =IF('INPUT DATA'!S22="","",'INPUT DATA'!S22) | I78: =IF(H78="","",DATEDIF(H78,TODAY(),"Y"))
B79: 13 | C79: =IF('INPUT DATA'!Q23="","",'INPUT DATA'!Q23) | F79: =IF('INPUT DATA'!T23="","",'INPUT DATA'!T23) | H79: =IF('INPUT DATA'!S23="","",'INPUT DATA'!S23) | I79: =IF(H79="","",DATEDIF(H79,TODAY(),"Y"))
...

Sheet SF9 - GRADE 11 ACADEMIC
B4: Republic of the Philippines | Q4: Month | R4: Jun | S4: Jul | T4: Aug | U4: Sep | V4: Oct | W4: Nov | X4: Dec | Y4: Jan | Z4: Feb | AA4: Mar | AB4: Apr | AC4: Total
B5: Department of Education | Q5: No. of Class Days | AC5: =SUM(R5:AB6) -> 0
B7: REGION | Q7: No. of Days Present | AC7: =SUM(R7:AB8) -> 0
B8: SCHOOLS DIVISION OFFICE OF AGUSAN DEL SUR
B9: Prosperidad District | Q9: No. of Days Absent | Z9: =IF(Z7="","",ABS(Z5-Z7)) | AC9: =ABS(AC5-AC7) -> 0
B10: Prosperidad, Agusan del Sur
B12: AGUSAN DEL SUR NATIONAL SCIENCE HIGH SCHOOL
B14: LEARNER'S PERFORMANCE REPORT | Q14: TEACHER'S COMMENTS / REMARKS
B15: School Year 2026-2027 | Q15: Term 1
B17: Name: | H17: Age: | I17: =IF(C17="","",VLOOKUP(C17,'TERM 1 SUMMARY'!C16:R116,7,0)) | J17: Sex: | K17: =IF(C17="","",VLOOKUP(C17,'TERM 1 SUMMARY'!C16:R116,8,0))
B18: LRN: | C18: =IF(C17="","",VLOOKUP(C17,'TERM 1 SUMMARY'!C16:R116,4,0)) | H18: Grade: | I18: =IF('INPUT DATA'!F27="","",'INPUT DATA'!F27) | J18: Section: | K18: =IF('INPUT DATA'!F29="","",'INPUT DATA'!F29)
B19: Track (SHS only): | E19: =IF('INPUT DATA'!F28="","",'INPUT DATA'!F28) | Q19: Term 2
B21: Dear Parents,
C22: This Performance Report presents your child's progress and achievement
B23: in the different learning areas. | Q23: Term 3
C24: The school welcomes you to reach out should you wish to know more about your
B25: child's learning and performance.
B27: =IF('INPUT DATA'!F19="","",'INPUT DATA'!F19) | H27: =IF('INPUT DATA'!F26="","",'INPUT DATA'!F26)
B28: School Head | H28: Adviser
B29: LEARNING PROGRESS AND ACHIEVEMENT | Q29: PARENT/S GUARDIAN'S SIGNATURE
B30: Learning Areas | F30: TERM | I30: Units | J30: Final Grade | K30: Remarks | R30: Term 1
F31: T1 | G31: T2 | H31: T3 | R31: Term 2
B32: Core Subjects | R32: Term 3
B33: Media and Information Literacy | F33: =IF('TERM 1 SUMMARY'!K16="","",VLOOKUP(C17,'TERM 1 SUMMARY'!C16:R116,9,0)) | G33: =IF('TERM 2 SUMMARY'!K16="","",VLOOKUP(C17,'TERM 2 SUMMARY'!C16:R116,11,0)) | H33: =IF('TERM 3 SUMMARY'!K16="","",VLOOKUP(C17,'TERM 3 SUMMARY'!C16:R116,11,0)) | J33: =IF(SUM(F33:H33)=0, "", ROUND((F33+H33+G33)*(I33/3)/I33,0)) | K33: =IF(J33="", "", IF(J33>=75, "Passed", "Failed")) | L33: =J33*I33 -> #VALUE!
B34: PE and Health 3 | F34: =IF('TERM 1 SUMMARY'!K16="","",VLOOKUP(C17,'TERM 1 SUMMARY'!C16:R116,10,0)) | G34: =IF('TERM 2 SUMMARY'!K16="","",VLOOKUP(C17,'TERM 2 SUMMARY'!C16:R116,11,0)) | H34: =IF('TERM 3 SUMMARY'!K16="","",VLOOKUP(C17,'TERM 3 SUMMARY'!C16:R116,11,0))
B35: Introduction to Human Philosophy | F35: =IF('TERM 1 SUMMARY'!K16="","",VLOOKUP(C17,'TERM 1 SUMMARY'!C16:R116,11,0)) | G35: =IF('TERM 2 SUMMARY'!K16="","",VLOOKUP(C17,'TERM 2 SUMMARY'!C16:R116,10,0)) | H35: =IF('TERM 3 SUMMARY'!K16="","",VLOOKUP(C17,'TERM 3 SUMMARY'!C16:R116,10,0)) | Q35: CERTIFICATE OF TRANSFER | AE35: =IF(COUNT(F31:H31)=0,"",ROUND((F31+G31+H31)/3,0))
B36: Disaster Readiness and Risk Reduction | F36: =IF('TERM 1 SUMMARY'!K16="","",VLOOKUP(C17,'TERM 1 SUMMARY'!C16:R116,12,0)) | G36: =IF('TERM 2 SUMMARY'!K16="","",VLOOKUP(C17,'TERM 2 SUMMARY'!C16:R116,12,0)) | H36: =IF('TERM 3 SUMMARY'!K16="","",VLOOKUP(C17,'TERM 3 SUMMARY'!C16:R116,12,0)) | J36: =IF(SUM(F36:H36)=0, "", ROUND((F36+H36+G36)*(I36/3)/I36,0)) | K36: =IF(J36="", "", IF(J36>=75, "Passed", "Failed")) | L36: =J36*I36 -> #VALUE! | Q36: This is to certify that the above-named learner has satisfactorily completed the requirements
B37: Contemporary Philippine Arts | F37: =IF('TERM 1 SUMMARY'!K16="","",VLOOKUP(C17,'TERM 1 SUMMARY'!C16:R116,13,0)) | G37: =IF('TERM 2 SUMMARY'!K16="","",VLOOKUP(C17,'TERM 2 SUMMARY'!C16:R116,13,0)) | H37: =IF('TERM 3 SUMMARY'!K16="","",VLOOKUP(C17,'TERM 3 SUMMARY'!C16:R116,13,0)) | J37: =IF(SUM(F37:H37)=0, "", ROUND((F37+H37+G37)*(I37/3)/I37,0)) | K37: =IF(J37="", "", IF(J37>=75, "Passed", "Failed")) | L37: =J37*I37 -> #VALUE! | Q37: for the grade level indicated.
B38: PE and Health 4
B39: Applied and Specialized Subjects | L39: =#REF!*#REF! -> #REF!
B40: Filipino sa Piling Larang | Q40: Admitted to Grade:
B41: Practical Research 2 | L41: =#REF!*#REF! -> #REF!
B42: General Biology 1 | Q42: Eligible for Admission to Grade:
B43: General Physics 1 | L43: =#REF!*#REF! -> #REF!
B44: English for Academic & Professional Purposes | L44: =#REF!*#REF! -> #REF! | X44: =IF('INPUT DATA'!F29="","",'INPUT DATA'!F29)
B45: Entrepreneurship | L45: =#REF!*#REF! -> #REF! | Q45: Approved: | X45: Adviser
B46: General Physics 2 | L46: =SUM(L33:L45) -> #VALUE!
B47: General Biology 2 | L47: =SUM(L34:L46) -> #VALUE!
Q48: =IF('INPUT DATA'!F24="","",'INPUT DATA'!F24)
B49: Inquiries, Investigation and Immersion
...

Sheet HELPER
B2: HELPER
B3: IMPORTANT / DO NOT DELETE
B5: CLUSTERS OF ELECTIVES | E5: ACADEMIC ELECTIVES | I5: TECHPRO ELECTIVES
B6: Academic | E6: Cluster of Electives | F6: Subjects | G6: Units per Term | I6: Cluster of Electives | J6: Subjects | K6: Units per Term
B7: Arts, Social Sciences, and Humanities | E7: ARTS, SOCIAL SCIENCES, AND HUMANITIES | F7: Art Criticism and Creative Markets | G7: 3 | I7: AESTHETIC, WELLNESS, AND HUMAN CARE | J7: Aesthetic Services (Beauty Care) | K7: 4
B8: Business and Entrepreneurship | F8: Creative Industries - Visual Arts | G8: 3 | J8: Caregiving (Adult Care) | K8: 4
B9: Science, Technology, Engineering, and Mathematics | F9: Creative Industries - Literary Arts | G9: 3 | J9: Caregiving (Child Care) | K9: 4
B10: Sports, Health, and Wellness | F10: Creative Industries - Media Arts | G10: 3 | J10: Hairdressing Services | K10: 4
B11: Field Experience | F11: Creative Industries - Applied and Traditional Arts | G11: 3 | I11: AGRI-FISHERY BUSINESS AND FOOD INNOVATION | J11: Agricultural Crops Production | K11: 4
B12: TechPro | F12: Creative Industries - Music | G12: 3 | J12: Agro-entrepreneurship | K12: 4
B13: Aesthetic, Wellness, and Human Care | F13: Creative Industries - Dance | G13: 3 | J13: Aquaculture | K13: 4
B14: Afri-Fishery Business and Food Innovation | F14: Creative Industries - Theater Arts | G14: 3 | J14: Fish Capture Operation | K14: 4
B15: Artisanry and Creative Enterprise | F15: Citizenship and Civic Engagement | G15: 3 | J15: Food Processing | K15: 4
B16: Automotive and Small Engine Technologies | F16: Contemporary Literature 1 | G16: 3 | J16: Organic Agriculture Production | K16: 4
B17: Constructiton and Building Technologies | F17: Contemporary Literature 2 | G17: 3 | J17: Poultry Production (Chicken) | K17: 4
B18: Creative Arts and Design Technologies | F18: Creative Composition 1 | G18: 3 | J18: Ruminants Production | K18: 4
B19: Hospital and Tourism | F19: Creative Composition 2 | G19: 3 | J19: Swine Production | K19: 4
B20: ICT Support and Computer Programming Technologies | F20: Creative Production and Presentation | G20: 6 | I20: ARTISANRY AND CREATIVE ENTERPRISE | J20: Garments Artisanry | K20: 4
B21: Industrial Technologies | F21: Filipino 1 (Wika at Komunikasyon sa Akademikong Filipino) | G21: 3 | J21: Handicrafts: Weaving | K21: 4
B22: Maritime | F22: Filipino 2 (Filipino sa Isports) | G22: 3 | I22: AUTOMOTIVE AND SMALL ENGINE TECHNOLOGIES | J22: Automotive Servicing (Electrical Repair) | K22: 4
F23: Filipino 2 (Filipino sa Sining at Disenyo) | G23: 3 | J23: Automotive Servicing (Engine and Chassis Repairs) | K23: 4
F24: Filipino 2 (Filipino sa Larang Teknikal-Propesyonal) | G24: 3 | J24: Driving and Automotive Servicing | K24: 4
B25: CORE SUBJECTS | C25: UNITS | F25: Filipino Identity Through the Arts | G25: 3 | J25: Motorcycle and Small Engine Servicing | K25: 4
B26: Effective Communication/ Mabisang Komunikasyon | C26: 2 | F26: Introduction to the Philosophy of the Human Person | G26: 3 | I26: CONSTRUCTION AND BUILDING TECHNOLOGIES | J26: Carpentry | K26: 4
B27: General Mathematics | C27: 2 | F27: Leadership and Management in the Arts | G27: 3 | J27: Construction Operation | K27: 4
B28: General Science | C28: 2 | F28: Malikhaing Pagsulat | G28: 3 | J28: Manual Metal Arc Welding | K28: 4
B29: Life and Career Skills | C29: 2 | F29: Performance Criticism and Creative Markets | G29: 3 | J29: Technical Drafting | K29: 4
B30: Pag-aaral ng Kasaysayan at Lipunang Pilipino | C30: 2 | F30: Philippine Governance (Philippine Politics and Governance) | G30: 3 | I30: CREATIVE ARTS AND DESIGN TECHNOLOGIES | J30: Animation | K30: 4
F31: Social Sciences (Theory and Practice) | G31: 3 | J31: Illustration | K31: 4
E32: BUSINESS AND ENTREPRENEURSHIP | F32: Business 1 (Basic Accounting) | G32: 3 | J32: Visual Graphic Design | K32: 4
F33: Business 2 (Business Finance and Income Taxation) | G33: 3 | I33: HOSPITALITY AND TOURISM | J33: Bakery Operations | K33: 4
F34: Business 3 (Business Economics) | G34: 3 | J34: Events Management Services | K34: 4
F35: Contemporary Marketing | G35: 3 | J35: Food and Beverage Operation | K35: 4
F36: Entrepreneurship | G36: 3 | J36: Hotel Operations (Front Office Services) | K36: 4
F37: Introduction to Organization and Management | G37: 3 | J37: Hotel Operations (Housekeeping Services) | K37: 4
E38: SCIENCE, TECHNOLOGY, ENGINEERING, AND MATHEMATICS | F38: Advanced Mathematics | G38: 3 | J38: Kitchen Operations | K38: 4
F39: Basic Calculus | G39: 3 | J39: Tourism Services | K39: 4
F40: Biology 1 | G40: 3 | I40: INDUSTRIAL TECHNOLOGIES | J40: Commercial Air-Conditioning Installation and Servicing | K40: 4
F41: Biology 2 | G41: 3 | J41: Domestic Refrigeration and Air-Conditioning Servicing | K41: 4
F42: Biology 3 | G42: 3 | J42: Electrical Installation and Maintenance | K42: 4
...
